2025-08-15 12:44:16,773 INFO API server STARTED
2025-08-15 12:44:16,776 INFO Start base migration
2025-08-15 12:44:52,342 INFO API server STARTED
2025-08-15 12:44:52,344 INFO Start base migration
2025-08-15 12:45:29,016 INFO API server STARTED
2025-08-15 12:45:29,019 INFO Start base migration
2025-08-15 12:45:58,900 INFO API - handle /start-sync request
2025-08-15 12:45:58,904 INFO START
2025-08-15 12:45:59,281 INFO START Synchronization..
2025-08-15 12:47:13,076 INFO Synchronization COMPLETED. Added 2428 servers in service database
2025-08-15 12:47:13,099 INFO END
2025-08-15 12:49:33,279 INFO API - handle /start-sync request
2025-08-15 12:49:33,322 INFO START
2025-08-15 12:49:33,324 INFO START Synchronization..
2025-08-15 12:55:29,121 INFO END
2025-08-15 12:55:29,877 ERROR Unclosed connection
connection: <aioodbc.connection.Connection object at 0x00000150ABE05D30>
2025-08-15 12:55:29,887 ERROR Unclosed connection
connection: <aioodbc.connection.Connection object at 0x00000150ABEB34D0>
2025-08-15 12:55:52,692 INFO API server STARTED
2025-08-15 12:55:52,695 INFO Start base migration
2025-08-15 12:56:11,482 INFO API - handle /start-sync request
2025-08-15 12:56:11,508 INFO START
2025-08-15 12:56:11,779 INFO START Synchronization..
2025-08-15 13:02:13,422 INFO END
2025-08-15 13:02:14,104 ERROR Unclosed connection
connection: <aioodbc.connection.Connection object at 0x000001722524E660>
2025-08-15 13:04:17,118 INFO API - handle /start-sync request
2025-08-15 13:04:17,125 INFO START
2025-08-15 13:04:17,308 INFO START Synchronization..
2025-08-15 13:08:41,270 INFO END
2025-08-15 13:10:14,058 INFO API server STARTED
2025-08-15 13:10:14,061 INFO Start base migration
2025-08-15 13:10:29,119 INFO API - handle /start-sync request
2025-08-15 13:10:29,124 INFO START
2025-08-15 13:10:29,274 INFO START Synchronization..
2025-08-15 13:12:19,750 ERROR Synchronization FAILED. In functions/sync_data.py: 'detected'
2025-08-15 13:12:19,797 INFO END
2025-08-15 13:14:41,598 INFO API server STARTED
2025-08-15 13:14:41,601 INFO Start base migration
2025-08-15 13:15:09,341 INFO API - handle /start-sync request
2025-08-15 13:15:09,350 INFO START
2025-08-15 13:15:09,547 INFO START Synchronization..
2025-08-15 13:15:55,219 ERROR Synchronization FAILED. In functions/sync_data.py: 'detected'
2025-08-15 13:15:55,297 INFO END
2025-08-15 13:15:55,941 ERROR Unclosed connection
connection: <aioodbc.connection.Connection object at 0x0000022044D1A3C0>
2025-08-15 13:16:15,009 INFO API server STARTED
2025-08-15 13:16:15,011 INFO Start base migration
2025-08-15 13:17:36,792 INFO API - handle /start-sync request
2025-08-15 13:17:36,797 INFO START
2025-08-15 13:17:36,964 INFO START Synchronization..
2025-08-15 13:22:20,498 INFO Synchronization COMPLETED. Added 0 servers in service database
2025-08-15 13:22:20,568 INFO END
2025-08-15 13:22:54,131 ERROR Unclosed connection
connection: <aioodbc.connection.Connection object at 0x0000028BDFBCE3C0>
2025-08-15 13:25:00,830 INFO API - handle /start-sync request
2025-08-15 13:25:00,840 INFO START
2025-08-15 13:25:01,035 INFO START Synchronization..
2025-08-15 13:29:10,224 INFO Synchronization COMPLETED. Added 0 servers in service database
2025-08-15 13:29:10,281 INFO END
2025-08-15 13:41:38,022 INFO API server STARTED
2025-08-15 13:41:38,024 INFO Start base migration
2025-08-15 13:41:48,623 INFO API - handle /start-sync request
2025-08-15 13:41:48,627 INFO START
2025-08-15 13:41:48,802 INFO START Synchronization..
2025-08-15 13:45:12,164 INFO API server STARTED
2025-08-15 13:45:12,166 INFO Start base migration
2025-08-15 13:45:26,434 INFO API - handle /start-sync request
2025-08-15 13:45:26,439 INFO START
2025-08-15 13:45:26,610 INFO START Synchronization..
2025-08-15 13:46:47,126 INFO API server STARTED
2025-08-15 13:46:47,129 INFO Start base migration
2025-08-15 13:47:00,023 INFO API - handle /start-sync request
2025-08-15 13:47:00,029 INFO START
2025-08-15 13:47:00,199 INFO START Synchronization..
2025-08-15 13:53:54,395 INFO API server STARTED
2025-08-15 13:53:54,398 INFO Start base migration
2025-08-15 13:54:23,204 INFO API - handle /start-sync request
2025-08-15 13:54:23,210 INFO START
2025-08-15 13:54:23,375 INFO START Synchronization..
2025-08-15 13:56:21,247 INFO API server STARTED
2025-08-15 13:56:21,250 INFO Start base migration
2025-08-15 13:56:38,160 INFO API - handle /start-sync request
2025-08-15 13:56:38,166 INFO START
2025-08-15 13:56:38,310 INFO START Synchronization..
2025-08-15 14:00:35,703 INFO Synchronization COMPLETED. Added 0 servers in service database
2025-08-15 14:00:35,759 INFO END
2025-08-15 14:01:09,016 ERROR Unclosed connection
connection: <aioodbc.connection.Connection object at 0x000002358196E3C0>
2025-08-15 14:01:44,445 INFO API server STARTED
2025-08-15 14:01:44,447 INFO Start base migration
2025-08-15 14:02:14,039 INFO API - handle /start-sync request
2025-08-15 14:02:14,045 INFO START
2025-08-15 14:02:14,220 INFO START Synchronization..
2025-08-15 14:03:09,749 INFO API server STARTED
2025-08-15 14:03:09,751 INFO Start base migration
2025-08-15 14:03:20,368 INFO API - handle /start-sync request
2025-08-15 14:03:20,394 INFO START
2025-08-15 14:03:20,536 INFO START Synchronization..
2025-08-15 14:09:52,887 INFO API server STARTED
2025-08-15 14:09:52,889 INFO Start base migration
2025-08-15 14:10:05,655 INFO API - handle /start-sync request
2025-08-15 14:10:05,660 INFO START
2025-08-15 14:10:05,862 INFO START Synchronization..
2025-08-15 14:13:07,514 INFO Synchronization COMPLETED. Added 0 servers in service database
2025-08-15 14:14:25,525 INFO END
2025-08-15 14:14:26,745 ERROR Unclosed connection
connection: <aioodbc.connection.Connection object at 0x00000259C827E3C0>
2025-08-15 17:38:42,865 INFO API server STARTED
2025-08-15 17:38:42,865 INFO Start base migration
2025-08-15 17:38:54,590 INFO API server STARTED
2025-08-15 17:38:54,590 INFO Start base migration
2025-08-15 17:39:34,064 INFO API - handle /start-sync request
2025-08-15 17:39:34,066 INFO START
2025-08-15 17:39:34,218 INFO START Synchronization..
2025-08-15 17:39:34,801 ERROR Synchronization FAILED. In functions/sync_data.py: ('classes/LansweeperDatabase.py -> LansweeperDatabase.get_mapped_custom_names -> ', KeyError('display_name'))
2025-08-15 17:39:35,026 INFO END
2025-08-15 17:39:46,395 ERROR Unclosed connection
connection: <aioodbc.connection.Connection object at 0x00000276F8EE12B0>
2025-08-15 17:40:38,516 INFO API server STARTED
2025-08-15 17:40:38,516 INFO Start base migration
2025-08-15 17:40:45,734 INFO API - handle /start-sync request
2025-08-15 17:40:45,737 INFO START
2025-08-15 17:40:45,847 INFO START Synchronization..
2025-08-15 17:40:46,354 ERROR Synchronization FAILED. In functions/sync_data.py: ('classes/LansweeperDatabase.py -> LansweeperDatabase.get_mapped_custom_names -> ', KeyError('Displayname'))
2025-08-15 17:40:46,659 INFO END
2025-08-15 17:41:12,794 ERROR Unclosed connection
connection: <aioodbc.connection.Connection object at 0x00000279863A5940>
2025-08-15 17:41:16,706 INFO API - handle /start-sync request
2025-08-15 17:41:16,709 INFO START
2025-08-15 17:41:16,813 INFO START Synchronization..
2025-08-15 17:41:17,173 ERROR Synchronization FAILED. In functions/sync_data.py: ('classes/LansweeperDatabase.py -> LansweeperDatabase.get_mapped_custom_names -> ', KeyError('Displayname'))
2025-08-15 17:41:17,450 INFO END
2025-08-15 17:41:37,880 ERROR Unclosed connection
connection: <aioodbc.connection.Connection object at 0x000001C535755940>
2025-08-15 17:41:56,490 INFO API server STARTED
2025-08-15 17:41:56,493 INFO Start base migration
2025-08-15 17:44:10,561 INFO API - handle /start-sync request
2025-08-15 17:44:10,564 INFO START
2025-08-15 17:44:10,646 INFO START Synchronization..
2025-08-15 17:44:11,012 ERROR Synchronization FAILED. In functions/sync_data.py: ('classes/LansweeperDatabase.py -> LansweeperDatabase.get_mapped_custom_names -> ', KeyError('Displayname'))
2025-08-15 17:44:11,246 INFO END
2025-08-15 17:44:40,765 INFO API - handle /start-sync request
2025-08-15 17:44:40,767 INFO START
2025-08-15 17:44:40,769 INFO START Synchronization..
2025-08-15 17:44:41,014 ERROR Synchronization FAILED. In functions/sync_data.py: ('classes/LansweeperDatabase.py -> LansweeperDatabase.get_mapped_custom_names -> ', KeyError('Displayname'))
2025-08-15 17:44:41,246 INFO END
2025-08-15 17:46:18,935 INFO API server STARTED
2025-08-15 17:46:18,938 INFO Start base migration
2025-08-15 17:46:30,519 INFO API - handle /start-sync request
2025-08-15 17:46:30,521 INFO START
2025-08-15 17:46:30,524 INFO START Synchronization..
2025-08-15 17:46:30,723 ERROR Synchronization FAILED. In functions/sync_data.py: ('classes/LansweeperDatabase.py -> LansweeperDatabase.get_mapped_custom_names -> ', KeyError('Displayname'))
2025-08-15 17:46:30,939 INFO END
2025-08-15 17:48:03,367 ERROR Unclosed connection
connection: <aioodbc.connection.Connection object at 0x000001E0D75A87D0>
2025-08-15 17:48:03,380 ERROR Unclosed connection
connection: <aioodbc.connection.Connection object at 0x000001E0D75A9A90>
2025-08-15 17:48:03,390 ERROR Unclosed connection
connection: <aioodbc.connection.Connection object at 0x000001E0D74F5940>
2025-08-15 17:48:16,728 INFO API - handle /start-sync request
2025-08-15 17:48:16,730 INFO START
2025-08-15 17:48:16,879 INFO START Synchronization..
2025-08-15 17:48:17,244 ERROR Synchronization FAILED. In functions/sync_data.py: ('classes/LansweeperDatabase.py -> LansweeperDatabase.get_mapped_custom_names -> ', KeyError('Customname'))
2025-08-15 17:48:17,470 INFO END
2025-08-15 17:48:31,579 INFO API - handle /start-sync request
2025-08-15 17:48:31,581 INFO START
2025-08-15 17:48:31,583 INFO START Synchronization..
2025-08-15 17:48:31,813 ERROR Synchronization FAILED. In functions/sync_data.py: ('classes/LansweeperDatabase.py -> LansweeperDatabase.get_mapped_custom_names -> ', KeyError('Customname'))
2025-08-15 17:48:32,020 INFO END
2025-08-15 17:48:57,754 ERROR Unclosed connection
connection: <aioodbc.connection.Connection object at 0x000001A4D0158910>
2025-08-15 17:48:57,764 ERROR Unclosed connection
connection: <aioodbc.connection.Connection object at 0x000001A4D00A5940>
2025-08-15 17:49:08,927 INFO API - handle /start-sync request
2025-08-15 17:49:08,931 INFO START
2025-08-15 17:49:09,047 INFO START Synchronization..
2025-08-15 17:49:09,432 ERROR Synchronization FAILED. In functions/sync_data.py: ('classes/LansweeperDatabase.py -> LansweeperDatabase.get_mapped_custom_names -> ', KeyError('Customname'))
2025-08-15 17:49:09,675 INFO END
2025-08-15 17:50:14,593 ERROR Unclosed connection
connection: <aioodbc.connection.Connection object at 0x000002574C03DA90>
2025-08-15 17:50:19,827 INFO API - handle /start-sync request
2025-08-15 17:50:19,836 INFO START
2025-08-15 17:50:19,946 INFO START Synchronization..
2025-08-15 17:50:20,291 ERROR Synchronization FAILED. In functions/sync_data.py: ('classes/LansweeperDatabase.py -> LansweeperDatabase.get_mapped_custom_names -> ', KeyError('Customname'))
2025-08-15 17:50:20,542 INFO END
2025-08-15 17:50:31,451 ERROR Unclosed connection
connection: <aioodbc.connection.Connection object at 0x0000023D5F6457F0>
2025-08-15 17:50:34,923 INFO API - handle /start-sync request
2025-08-15 17:50:34,925 INFO START
2025-08-15 17:50:35,035 INFO START Synchronization..
2025-08-15 17:50:35,394 ERROR Synchronization FAILED. In functions/sync_data.py: ('classes/LansweeperDatabase.py -> LansweeperDatabase.get_mapped_custom_names -> ', KeyError('Displayname'))
2025-08-15 17:50:35,831 INFO END
2025-08-15 17:54:02,042 ERROR Unclosed connection
connection: <aioodbc.connection.Connection object at 0x0000026A034F57F0>
2025-08-15 17:56:01,559 INFO API - handle /start-sync request
2025-08-15 17:56:01,562 INFO START
2025-08-15 17:56:01,668 INFO START Synchronization..
2025-08-15 17:56:02,710 ERROR Synchronization FAILED. In functions/sync_data.py: 'AssetID'
2025-08-15 17:56:02,739 INFO END
2025-08-15 17:57:26,903 ERROR Unclosed connection
connection: <aioodbc.connection.Connection object at 0x000002192F4657F0>
2025-08-15 17:57:33,115 INFO API - handle /start-sync request
2025-08-15 17:57:33,117 INFO START
2025-08-15 17:57:33,364 INFO START Synchronization..
2025-08-15 17:57:34,381 ERROR Synchronization FAILED. In functions/sync_data.py: 'Custom1'
2025-08-15 17:57:34,410 INFO END
2025-08-15 17:58:14,658 ERROR Unclosed connection
connection: <aioodbc.connection.Connection object at 0x000001E7467E57F0>
2025-08-15 17:58:19,075 INFO API - handle /start-sync request
2025-08-15 17:58:19,087 INFO START
2025-08-15 17:58:19,207 INFO START Synchronization..
2025-08-15 17:58:20,203 ERROR Synchronization FAILED. In functions/sync_data.py: list index out of range
2025-08-15 17:58:20,232 INFO END
2025-08-15 17:58:39,907 ERROR Unclosed connection
connection: <aioodbc.connection.Connection object at 0x000001E0234257F0>
2025-08-15 17:58:44,270 INFO API - handle /start-sync request
2025-08-15 17:58:44,273 INFO START
2025-08-15 17:58:44,385 INFO START Synchronization..
2025-08-15 17:59:48,981 INFO Synchronization COMPLETED. Added 2433 servers in service database
2025-08-15 17:59:49,009 INFO END
2025-08-15 18:02:16,266 ERROR Unclosed connection
connection: <aioodbc.connection.Connection object at 0x0000027AEC4C57F0>
2025-08-15 18:02:58,531 INFO API server STARTED
2025-08-15 18:02:58,531 INFO Start base migration
2025-08-15 18:03:46,006 INFO API - handle /start-sync request
2025-08-15 18:03:46,008 INFO START
2025-08-15 18:03:46,128 INFO START Synchronization..
2025-08-15 18:03:47,133 ERROR Error during database select operation: connect() got an unexpected keyword argument 'client_encoding'
Traceback (most recent call last):
  File "C:\Users\Yakubov\Documents\Development\LansweeperDataService\src\classes\Database.py", line 31, in select
    result = await session.execute(query)
             ^^^^^^^^^^^^^^^^^^^^^^^^^^^^
  File "C:\Users\Yakubov\AppData\Local\pypoetry\Cache\virtualenvs\lansweeperdataservice-dSLrnmG5-py3.13\Lib\site-packages\sqlalchemy\ext\asyncio\session.py", line 463, in execute
    result = await greenlet_spawn(
             ^^^^^^^^^^^^^^^^^^^^^
    ...<6 lines>...
    )
    ^
  File "C:\Users\Yakubov\AppData\Local\pypoetry\Cache\virtualenvs\lansweeperdataservice-dSLrnmG5-py3.13\Lib\site-packages\sqlalchemy\util\_concurrency_py3k.py", line 190, in greenlet_spawn
    result = context.switch(*args, **kwargs)
  File "C:\Users\Yakubov\AppData\Local\pypoetry\Cache\virtualenvs\lansweeperdataservice-dSLrnmG5-py3.13\Lib\site-packages\sqlalchemy\orm\session.py", line 2365, in execute
    return self._execute_internal(
           ~~~~~~~~~~~~~~~~~~~~~~^
        statement,
        ^^^^^^^^^^
    ...<4 lines>...
        _add_event=_add_event,
        ^^^^^^^^^^^^^^^^^^^^^^
    )
    ^
  File "C:\Users\Yakubov\AppData\Local\pypoetry\Cache\virtualenvs\lansweeperdataservice-dSLrnmG5-py3.13\Lib\site-packages\sqlalchemy\orm\session.py", line 2241, in _execute_internal
    conn = self._connection_for_bind(bind)
  File "C:\Users\Yakubov\AppData\Local\pypoetry\Cache\virtualenvs\lansweeperdataservice-dSLrnmG5-py3.13\Lib\site-packages\sqlalchemy\orm\session.py", line 2110, in _connection_for_bind
    return trans._connection_for_bind(engine, execution_options)
           ~~~~~~~~~~~~~~~~~~~~~~~~~~^^^^^^^^^^^^^^^^^^^^^^^^^^^
  File "<string>", line 2, in _connection_for_bind
  File "C:\Users\Yakubov\AppData\Local\pypoetry\Cache\virtualenvs\lansweeperdataservice-dSLrnmG5-py3.13\Lib\site-packages\sqlalchemy\orm\state_changes.py", line 139, in _go
    ret_value = fn(self, *arg, **kw)
  File "C:\Users\Yakubov\AppData\Local\pypoetry\Cache\virtualenvs\lansweeperdataservice-dSLrnmG5-py3.13\Lib\site-packages\sqlalchemy\orm\session.py", line 1189, in _connection_for_bind
    conn = bind.connect()
  File "C:\Users\Yakubov\AppData\Local\pypoetry\Cache\virtualenvs\lansweeperdataservice-dSLrnmG5-py3.13\Lib\site-packages\sqlalchemy\engine\base.py", line 3273, in connect
    return self._connection_cls(self)
           ~~~~~~~~~~~~~~~~~~~~^^^^^^
  File "C:\Users\Yakubov\AppData\Local\pypoetry\Cache\virtualenvs\lansweeperdataservice-dSLrnmG5-py3.13\Lib\site-packages\sqlalchemy\engine\base.py", line 145, in __init__
    self._dbapi_connection = engine.raw_connection()
                             ~~~~~~~~~~~~~~~~~~~~~^^
  File "C:\Users\Yakubov\AppData\Local\pypoetry\Cache\virtualenvs\lansweeperdataservice-dSLrnmG5-py3.13\Lib\site-packages\sqlalchemy\engine\base.py", line 3297, in raw_connection
    return self.pool.connect()
           ~~~~~~~~~~~~~~~~~^^
  File "C:\Users\Yakubov\AppData\Local\pypoetry\Cache\virtualenvs\lansweeperdataservice-dSLrnmG5-py3.13\Lib\site-packages\sqlalchemy\pool\base.py", line 449, in connect
    return _ConnectionFairy._checkout(self)
           ~~~~~~~~~~~~~~~~~~~~~~~~~~^^^^^^
  File "C:\Users\Yakubov\AppData\Local\pypoetry\Cache\virtualenvs\lansweeperdataservice-dSLrnmG5-py3.13\Lib\site-packages\sqlalchemy\pool\base.py", line 1264, in _checkout
    fairy = _ConnectionRecord.checkout(pool)
  File "C:\Users\Yakubov\AppData\Local\pypoetry\Cache\virtualenvs\lansweeperdataservice-dSLrnmG5-py3.13\Lib\site-packages\sqlalchemy\pool\base.py", line 713, in checkout
    rec = pool._do_get()
  File "C:\Users\Yakubov\AppData\Local\pypoetry\Cache\virtualenvs\lansweeperdataservice-dSLrnmG5-py3.13\Lib\site-packages\sqlalchemy\pool\impl.py", line 179, in _do_get
    with util.safe_reraise():
         ~~~~~~~~~~~~~~~~~^^
  File "C:\Users\Yakubov\AppData\Local\pypoetry\Cache\virtualenvs\lansweeperdataservice-dSLrnmG5-py3.13\Lib\site-packages\sqlalchemy\util\langhelpers.py", line 224, in __exit__
    raise exc_value.with_traceback(exc_tb)
  File "C:\Users\Yakubov\AppData\Local\pypoetry\Cache\virtualenvs\lansweeperdataservice-dSLrnmG5-py3.13\Lib\site-packages\sqlalchemy\pool\impl.py", line 177, in _do_get
    return self._create_connection()
           ~~~~~~~~~~~~~~~~~~~~~~~^^
  File "C:\Users\Yakubov\AppData\Local\pypoetry\Cache\virtualenvs\lansweeperdataservice-dSLrnmG5-py3.13\Lib\site-packages\sqlalchemy\pool\base.py", line 390, in _create_connection
    return _ConnectionRecord(self)
  File "C:\Users\Yakubov\AppData\Local\pypoetry\Cache\virtualenvs\lansweeperdataservice-dSLrnmG5-py3.13\Lib\site-packages\sqlalchemy\pool\base.py", line 675, in __init__
    self.__connect()
    ~~~~~~~~~~~~~~^^
  File "C:\Users\Yakubov\AppData\Local\pypoetry\Cache\virtualenvs\lansweeperdataservice-dSLrnmG5-py3.13\Lib\site-packages\sqlalchemy\pool\base.py", line 901, in __connect
    with util.safe_reraise():
         ~~~~~~~~~~~~~~~~~^^
  File "C:\Users\Yakubov\AppData\Local\pypoetry\Cache\virtualenvs\lansweeperdataservice-dSLrnmG5-py3.13\Lib\site-packages\sqlalchemy\util\langhelpers.py", line 224, in __exit__
    raise exc_value.with_traceback(exc_tb)
  File "C:\Users\Yakubov\AppData\Local\pypoetry\Cache\virtualenvs\lansweeperdataservice-dSLrnmG5-py3.13\Lib\site-packages\sqlalchemy\pool\base.py", line 897, in __connect
    self.dbapi_connection = connection = pool._invoke_creator(self)
                                         ~~~~~~~~~~~~~~~~~~~~^^^^^^
  File "C:\Users\Yakubov\AppData\Local\pypoetry\Cache\virtualenvs\lansweeperdataservice-dSLrnmG5-py3.13\Lib\site-packages\sqlalchemy\engine\create.py", line 646, in connect
    return dialect.connect(*cargs, **cparams)
           ~~~~~~~~~~~~~~~^^^^^^^^^^^^^^^^^^^
  File "C:\Users\Yakubov\AppData\Local\pypoetry\Cache\virtualenvs\lansweeperdataservice-dSLrnmG5-py3.13\Lib\site-packages\sqlalchemy\engine\default.py", line 625, in connect
    return self.loaded_dbapi.connect(*cargs, **cparams)  # type: ignore[no-any-return]  # NOQA: E501
           ~~~~~~~~~~~~~~~~~~~~~~~~~^^^^^^^^^^^^^^^^^^^
  File "C:\Users\Yakubov\AppData\Local\pypoetry\Cache\virtualenvs\lansweeperdataservice-dSLrnmG5-py3.13\Lib\site-packages\sqlalchemy\dialects\postgresql\asyncpg.py", line 961, in connect
    await_only(creator_fn(*arg, **kw)),
               ~~~~~~~~~~^^^^^^^^^^^^
TypeError: connect() got an unexpected keyword argument 'client_encoding'
2025-08-15 18:03:47,158 ERROR Synchronization FAILED. In functions/sync_data.py: connect() got an unexpected keyword argument 'client_encoding'
2025-08-15 18:03:47,159 ERROR Error during database insert operation: connect() got an unexpected keyword argument 'client_encoding'
Traceback (most recent call last):
  File "C:\Users\Yakubov\Documents\Development\LansweeperDataService\src\classes\Database.py", line 53, in insert
    await session.execute(insert(table).values(values))
  File "C:\Users\Yakubov\AppData\Local\pypoetry\Cache\virtualenvs\lansweeperdataservice-dSLrnmG5-py3.13\Lib\site-packages\sqlalchemy\ext\asyncio\session.py", line 463, in execute
    result = await greenlet_spawn(
             ^^^^^^^^^^^^^^^^^^^^^
    ...<6 lines>...
    )
    ^
  File "C:\Users\Yakubov\AppData\Local\pypoetry\Cache\virtualenvs\lansweeperdataservice-dSLrnmG5-py3.13\Lib\site-packages\sqlalchemy\util\_concurrency_py3k.py", line 190, in greenlet_spawn
    result = context.switch(*args, **kwargs)
  File "C:\Users\Yakubov\AppData\Local\pypoetry\Cache\virtualenvs\lansweeperdataservice-dSLrnmG5-py3.13\Lib\site-packages\sqlalchemy\orm\session.py", line 2365, in execute
    return self._execute_internal(
           ~~~~~~~~~~~~~~~~~~~~~~^
        statement,
        ^^^^^^^^^^
    ...<4 lines>...
        _add_event=_add_event,
        ^^^^^^^^^^^^^^^^^^^^^^
    )
    ^
  File "C:\Users\Yakubov\AppData\Local\pypoetry\Cache\virtualenvs\lansweeperdataservice-dSLrnmG5-py3.13\Lib\site-packages\sqlalchemy\orm\session.py", line 2241, in _execute_internal
    conn = self._connection_for_bind(bind)
  File "C:\Users\Yakubov\AppData\Local\pypoetry\Cache\virtualenvs\lansweeperdataservice-dSLrnmG5-py3.13\Lib\site-packages\sqlalchemy\orm\session.py", line 2110, in _connection_for_bind
    return trans._connection_for_bind(engine, execution_options)
           ~~~~~~~~~~~~~~~~~~~~~~~~~~^^^^^^^^^^^^^^^^^^^^^^^^^^^
  File "<string>", line 2, in _connection_for_bind
  File "C:\Users\Yakubov\AppData\Local\pypoetry\Cache\virtualenvs\lansweeperdataservice-dSLrnmG5-py3.13\Lib\site-packages\sqlalchemy\orm\state_changes.py", line 139, in _go
    ret_value = fn(self, *arg, **kw)
  File "C:\Users\Yakubov\AppData\Local\pypoetry\Cache\virtualenvs\lansweeperdataservice-dSLrnmG5-py3.13\Lib\site-packages\sqlalchemy\orm\session.py", line 1189, in _connection_for_bind
    conn = bind.connect()
  File "C:\Users\Yakubov\AppData\Local\pypoetry\Cache\virtualenvs\lansweeperdataservice-dSLrnmG5-py3.13\Lib\site-packages\sqlalchemy\engine\base.py", line 3273, in connect
    return self._connection_cls(self)
           ~~~~~~~~~~~~~~~~~~~~^^^^^^
  File "C:\Users\Yakubov\AppData\Local\pypoetry\Cache\virtualenvs\lansweeperdataservice-dSLrnmG5-py3.13\Lib\site-packages\sqlalchemy\engine\base.py", line 145, in __init__
    self._dbapi_connection = engine.raw_connection()
                             ~~~~~~~~~~~~~~~~~~~~~^^
  File "C:\Users\Yakubov\AppData\Local\pypoetry\Cache\virtualenvs\lansweeperdataservice-dSLrnmG5-py3.13\Lib\site-packages\sqlalchemy\engine\base.py", line 3297, in raw_connection
    return self.pool.connect()
           ~~~~~~~~~~~~~~~~~^^
  File "C:\Users\Yakubov\AppData\Local\pypoetry\Cache\virtualenvs\lansweeperdataservice-dSLrnmG5-py3.13\Lib\site-packages\sqlalchemy\pool\base.py", line 449, in connect
    return _ConnectionFairy._checkout(self)
           ~~~~~~~~~~~~~~~~~~~~~~~~~~^^^^^^
  File "C:\Users\Yakubov\AppData\Local\pypoetry\Cache\virtualenvs\lansweeperdataservice-dSLrnmG5-py3.13\Lib\site-packages\sqlalchemy\pool\base.py", line 1264, in _checkout
    fairy = _ConnectionRecord.checkout(pool)
  File "C:\Users\Yakubov\AppData\Local\pypoetry\Cache\virtualenvs\lansweeperdataservice-dSLrnmG5-py3.13\Lib\site-packages\sqlalchemy\pool\base.py", line 713, in checkout
    rec = pool._do_get()
  File "C:\Users\Yakubov\AppData\Local\pypoetry\Cache\virtualenvs\lansweeperdataservice-dSLrnmG5-py3.13\Lib\site-packages\sqlalchemy\pool\impl.py", line 179, in _do_get
    with util.safe_reraise():
         ~~~~~~~~~~~~~~~~~^^
  File "C:\Users\Yakubov\AppData\Local\pypoetry\Cache\virtualenvs\lansweeperdataservice-dSLrnmG5-py3.13\Lib\site-packages\sqlalchemy\util\langhelpers.py", line 224, in __exit__
    raise exc_value.with_traceback(exc_tb)
  File "C:\Users\Yakubov\AppData\Local\pypoetry\Cache\virtualenvs\lansweeperdataservice-dSLrnmG5-py3.13\Lib\site-packages\sqlalchemy\pool\impl.py", line 177, in _do_get
    return self._create_connection()
           ~~~~~~~~~~~~~~~~~~~~~~~^^
  File "C:\Users\Yakubov\AppData\Local\pypoetry\Cache\virtualenvs\lansweeperdataservice-dSLrnmG5-py3.13\Lib\site-packages\sqlalchemy\pool\base.py", line 390, in _create_connection
    return _ConnectionRecord(self)
  File "C:\Users\Yakubov\AppData\Local\pypoetry\Cache\virtualenvs\lansweeperdataservice-dSLrnmG5-py3.13\Lib\site-packages\sqlalchemy\pool\base.py", line 675, in __init__
    self.__connect()
    ~~~~~~~~~~~~~~^^
  File "C:\Users\Yakubov\AppData\Local\pypoetry\Cache\virtualenvs\lansweeperdataservice-dSLrnmG5-py3.13\Lib\site-packages\sqlalchemy\pool\base.py", line 901, in __connect
    with util.safe_reraise():
         ~~~~~~~~~~~~~~~~~^^
  File "C:\Users\Yakubov\AppData\Local\pypoetry\Cache\virtualenvs\lansweeperdataservice-dSLrnmG5-py3.13\Lib\site-packages\sqlalchemy\util\langhelpers.py", line 224, in __exit__
    raise exc_value.with_traceback(exc_tb)
  File "C:\Users\Yakubov\AppData\Local\pypoetry\Cache\virtualenvs\lansweeperdataservice-dSLrnmG5-py3.13\Lib\site-packages\sqlalchemy\pool\base.py", line 897, in __connect
    self.dbapi_connection = connection = pool._invoke_creator(self)
                                         ~~~~~~~~~~~~~~~~~~~~^^^^^^
  File "C:\Users\Yakubov\AppData\Local\pypoetry\Cache\virtualenvs\lansweeperdataservice-dSLrnmG5-py3.13\Lib\site-packages\sqlalchemy\engine\create.py", line 646, in connect
    return dialect.connect(*cargs, **cparams)
           ~~~~~~~~~~~~~~~^^^^^^^^^^^^^^^^^^^
  File "C:\Users\Yakubov\AppData\Local\pypoetry\Cache\virtualenvs\lansweeperdataservice-dSLrnmG5-py3.13\Lib\site-packages\sqlalchemy\engine\default.py", line 625, in connect
    return self.loaded_dbapi.connect(*cargs, **cparams)  # type: ignore[no-any-return]  # NOQA: E501
           ~~~~~~~~~~~~~~~~~~~~~~~~~^^^^^^^^^^^^^^^^^^^
  File "C:\Users\Yakubov\AppData\Local\pypoetry\Cache\virtualenvs\lansweeperdataservice-dSLrnmG5-py3.13\Lib\site-packages\sqlalchemy\dialects\postgresql\asyncpg.py", line 961, in connect
    await_only(creator_fn(*arg, **kw)),
               ~~~~~~~~~~^^^^^^^^^^^^
TypeError: connect() got an unexpected keyword argument 'client_encoding'
2025-08-15 18:03:47,167 ERROR Synchronization error: connect() got an unexpected keyword argument 'client_encoding'
Traceback (most recent call last):
  File "C:\Users\Yakubov\Documents\Development\LansweeperDataService\src\sync.py", line 25, in sync
    await service.insert(
    ...<2 lines>...
    )
  File "C:\Users\Yakubov\Documents\Development\LansweeperDataService\src\classes\Database.py", line 58, in insert
    raise e
  File "C:\Users\Yakubov\Documents\Development\LansweeperDataService\src\classes\Database.py", line 53, in insert
    await session.execute(insert(table).values(values))
  File "C:\Users\Yakubov\AppData\Local\pypoetry\Cache\virtualenvs\lansweeperdataservice-dSLrnmG5-py3.13\Lib\site-packages\sqlalchemy\ext\asyncio\session.py", line 463, in execute
    result = await greenlet_spawn(
             ^^^^^^^^^^^^^^^^^^^^^
    ...<6 lines>...
    )
    ^
  File "C:\Users\Yakubov\AppData\Local\pypoetry\Cache\virtualenvs\lansweeperdataservice-dSLrnmG5-py3.13\Lib\site-packages\sqlalchemy\util\_concurrency_py3k.py", line 190, in greenlet_spawn
    result = context.switch(*args, **kwargs)
  File "C:\Users\Yakubov\AppData\Local\pypoetry\Cache\virtualenvs\lansweeperdataservice-dSLrnmG5-py3.13\Lib\site-packages\sqlalchemy\orm\session.py", line 2365, in execute
    return self._execute_internal(
           ~~~~~~~~~~~~~~~~~~~~~~^
        statement,
        ^^^^^^^^^^
    ...<4 lines>...
        _add_event=_add_event,
        ^^^^^^^^^^^^^^^^^^^^^^
    )
    ^
  File "C:\Users\Yakubov\AppData\Local\pypoetry\Cache\virtualenvs\lansweeperdataservice-dSLrnmG5-py3.13\Lib\site-packages\sqlalchemy\orm\session.py", line 2241, in _execute_internal
    conn = self._connection_for_bind(bind)
  File "C:\Users\Yakubov\AppData\Local\pypoetry\Cache\virtualenvs\lansweeperdataservice-dSLrnmG5-py3.13\Lib\site-packages\sqlalchemy\orm\session.py", line 2110, in _connection_for_bind
    return trans._connection_for_bind(engine, execution_options)
           ~~~~~~~~~~~~~~~~~~~~~~~~~~^^^^^^^^^^^^^^^^^^^^^^^^^^^
  File "<string>", line 2, in _connection_for_bind
  File "C:\Users\Yakubov\AppData\Local\pypoetry\Cache\virtualenvs\lansweeperdataservice-dSLrnmG5-py3.13\Lib\site-packages\sqlalchemy\orm\state_changes.py", line 139, in _go
    ret_value = fn(self, *arg, **kw)
  File "C:\Users\Yakubov\AppData\Local\pypoetry\Cache\virtualenvs\lansweeperdataservice-dSLrnmG5-py3.13\Lib\site-packages\sqlalchemy\orm\session.py", line 1189, in _connection_for_bind
    conn = bind.connect()
  File "C:\Users\Yakubov\AppData\Local\pypoetry\Cache\virtualenvs\lansweeperdataservice-dSLrnmG5-py3.13\Lib\site-packages\sqlalchemy\engine\base.py", line 3273, in connect
    return self._connection_cls(self)
           ~~~~~~~~~~~~~~~~~~~~^^^^^^
  File "C:\Users\Yakubov\AppData\Local\pypoetry\Cache\virtualenvs\lansweeperdataservice-dSLrnmG5-py3.13\Lib\site-packages\sqlalchemy\engine\base.py", line 145, in __init__
    self._dbapi_connection = engine.raw_connection()
                             ~~~~~~~~~~~~~~~~~~~~~^^
  File "C:\Users\Yakubov\AppData\Local\pypoetry\Cache\virtualenvs\lansweeperdataservice-dSLrnmG5-py3.13\Lib\site-packages\sqlalchemy\engine\base.py", line 3297, in raw_connection
    return self.pool.connect()
           ~~~~~~~~~~~~~~~~~^^
  File "C:\Users\Yakubov\AppData\Local\pypoetry\Cache\virtualenvs\lansweeperdataservice-dSLrnmG5-py3.13\Lib\site-packages\sqlalchemy\pool\base.py", line 449, in connect
    return _ConnectionFairy._checkout(self)
           ~~~~~~~~~~~~~~~~~~~~~~~~~~^^^^^^
  File "C:\Users\Yakubov\AppData\Local\pypoetry\Cache\virtualenvs\lansweeperdataservice-dSLrnmG5-py3.13\Lib\site-packages\sqlalchemy\pool\base.py", line 1264, in _checkout
    fairy = _ConnectionRecord.checkout(pool)
  File "C:\Users\Yakubov\AppData\Local\pypoetry\Cache\virtualenvs\lansweeperdataservice-dSLrnmG5-py3.13\Lib\site-packages\sqlalchemy\pool\base.py", line 713, in checkout
    rec = pool._do_get()
  File "C:\Users\Yakubov\AppData\Local\pypoetry\Cache\virtualenvs\lansweeperdataservice-dSLrnmG5-py3.13\Lib\site-packages\sqlalchemy\pool\impl.py", line 179, in _do_get
    with util.safe_reraise():
         ~~~~~~~~~~~~~~~~~^^
  File "C:\Users\Yakubov\AppData\Local\pypoetry\Cache\virtualenvs\lansweeperdataservice-dSLrnmG5-py3.13\Lib\site-packages\sqlalchemy\util\langhelpers.py", line 224, in __exit__
    raise exc_value.with_traceback(exc_tb)
  File "C:\Users\Yakubov\AppData\Local\pypoetry\Cache\virtualenvs\lansweeperdataservice-dSLrnmG5-py3.13\Lib\site-packages\sqlalchemy\pool\impl.py", line 177, in _do_get
    return self._create_connection()
           ~~~~~~~~~~~~~~~~~~~~~~~^^
  File "C:\Users\Yakubov\AppData\Local\pypoetry\Cache\virtualenvs\lansweeperdataservice-dSLrnmG5-py3.13\Lib\site-packages\sqlalchemy\pool\base.py", line 390, in _create_connection
    return _ConnectionRecord(self)
  File "C:\Users\Yakubov\AppData\Local\pypoetry\Cache\virtualenvs\lansweeperdataservice-dSLrnmG5-py3.13\Lib\site-packages\sqlalchemy\pool\base.py", line 675, in __init__
    self.__connect()
    ~~~~~~~~~~~~~~^^
  File "C:\Users\Yakubov\AppData\Local\pypoetry\Cache\virtualenvs\lansweeperdataservice-dSLrnmG5-py3.13\Lib\site-packages\sqlalchemy\pool\base.py", line 901, in __connect
    with util.safe_reraise():
         ~~~~~~~~~~~~~~~~~^^
  File "C:\Users\Yakubov\AppData\Local\pypoetry\Cache\virtualenvs\lansweeperdataservice-dSLrnmG5-py3.13\Lib\site-packages\sqlalchemy\util\langhelpers.py", line 224, in __exit__
    raise exc_value.with_traceback(exc_tb)
  File "C:\Users\Yakubov\AppData\Local\pypoetry\Cache\virtualenvs\lansweeperdataservice-dSLrnmG5-py3.13\Lib\site-packages\sqlalchemy\pool\base.py", line 897, in __connect
    self.dbapi_connection = connection = pool._invoke_creator(self)
                                         ~~~~~~~~~~~~~~~~~~~~^^^^^^
  File "C:\Users\Yakubov\AppData\Local\pypoetry\Cache\virtualenvs\lansweeperdataservice-dSLrnmG5-py3.13\Lib\site-packages\sqlalchemy\engine\create.py", line 646, in connect
    return dialect.connect(*cargs, **cparams)
           ~~~~~~~~~~~~~~~^^^^^^^^^^^^^^^^^^^
  File "C:\Users\Yakubov\AppData\Local\pypoetry\Cache\virtualenvs\lansweeperdataservice-dSLrnmG5-py3.13\Lib\site-packages\sqlalchemy\engine\default.py", line 625, in connect
    return self.loaded_dbapi.connect(*cargs, **cparams)  # type: ignore[no-any-return]  # NOQA: E501
           ~~~~~~~~~~~~~~~~~~~~~~~~~^^^^^^^^^^^^^^^^^^^
  File "C:\Users\Yakubov\AppData\Local\pypoetry\Cache\virtualenvs\lansweeperdataservice-dSLrnmG5-py3.13\Lib\site-packages\sqlalchemy\dialects\postgresql\asyncpg.py", line 961, in connect
    await_only(creator_fn(*arg, **kw)),
               ~~~~~~~~~~^^^^^^^^^^^^
TypeError: connect() got an unexpected keyword argument 'client_encoding'
2025-08-15 18:03:47,176 INFO END
2025-08-15 18:03:47,176 ERROR Task exception was never retrieved
future: <Task finished name='Task-5' coro=<sync() done, defined at C:\Users\Yakubov\Documents\Development\LansweeperDataService\src\sync.py:12> exception=TypeError("connect() got an unexpected keyword argument 'client_encoding'")>
Traceback (most recent call last):
  File "C:\Users\Yakubov\Documents\Development\LansweeperDataService\src\sync.py", line 32, in sync
    raise e
  File "C:\Users\Yakubov\Documents\Development\LansweeperDataService\src\sync.py", line 25, in sync
    await service.insert(
    ...<2 lines>...
    )
  File "C:\Users\Yakubov\Documents\Development\LansweeperDataService\src\classes\Database.py", line 58, in insert
    raise e
  File "C:\Users\Yakubov\Documents\Development\LansweeperDataService\src\classes\Database.py", line 53, in insert
    await session.execute(insert(table).values(values))
  File "C:\Users\Yakubov\AppData\Local\pypoetry\Cache\virtualenvs\lansweeperdataservice-dSLrnmG5-py3.13\Lib\site-packages\sqlalchemy\ext\asyncio\session.py", line 463, in execute
    result = await greenlet_spawn(
             ^^^^^^^^^^^^^^^^^^^^^
    ...<6 lines>...
    )
    ^
  File "C:\Users\Yakubov\AppData\Local\pypoetry\Cache\virtualenvs\lansweeperdataservice-dSLrnmG5-py3.13\Lib\site-packages\sqlalchemy\util\_concurrency_py3k.py", line 190, in greenlet_spawn
    result = context.switch(*args, **kwargs)
  File "C:\Users\Yakubov\AppData\Local\pypoetry\Cache\virtualenvs\lansweeperdataservice-dSLrnmG5-py3.13\Lib\site-packages\sqlalchemy\orm\session.py", line 2365, in execute
    return self._execute_internal(
           ~~~~~~~~~~~~~~~~~~~~~~^
        statement,
        ^^^^^^^^^^
    ...<4 lines>...
        _add_event=_add_event,
        ^^^^^^^^^^^^^^^^^^^^^^
    )
    ^
  File "C:\Users\Yakubov\AppData\Local\pypoetry\Cache\virtualenvs\lansweeperdataservice-dSLrnmG5-py3.13\Lib\site-packages\sqlalchemy\orm\session.py", line 2241, in _execute_internal
    conn = self._connection_for_bind(bind)
  File "C:\Users\Yakubov\AppData\Local\pypoetry\Cache\virtualenvs\lansweeperdataservice-dSLrnmG5-py3.13\Lib\site-packages\sqlalchemy\orm\session.py", line 2110, in _connection_for_bind
    return trans._connection_for_bind(engine, execution_options)
           ~~~~~~~~~~~~~~~~~~~~~~~~~~^^^^^^^^^^^^^^^^^^^^^^^^^^^
  File "<string>", line 2, in _connection_for_bind
  File "C:\Users\Yakubov\AppData\Local\pypoetry\Cache\virtualenvs\lansweeperdataservice-dSLrnmG5-py3.13\Lib\site-packages\sqlalchemy\orm\state_changes.py", line 139, in _go
    ret_value = fn(self, *arg, **kw)
  File "C:\Users\Yakubov\AppData\Local\pypoetry\Cache\virtualenvs\lansweeperdataservice-dSLrnmG5-py3.13\Lib\site-packages\sqlalchemy\orm\session.py", line 1189, in _connection_for_bind
    conn = bind.connect()
  File "C:\Users\Yakubov\AppData\Local\pypoetry\Cache\virtualenvs\lansweeperdataservice-dSLrnmG5-py3.13\Lib\site-packages\sqlalchemy\engine\base.py", line 3273, in connect
    return self._connection_cls(self)
           ~~~~~~~~~~~~~~~~~~~~^^^^^^
  File "C:\Users\Yakubov\AppData\Local\pypoetry\Cache\virtualenvs\lansweeperdataservice-dSLrnmG5-py3.13\Lib\site-packages\sqlalchemy\engine\base.py", line 145, in __init__
    self._dbapi_connection = engine.raw_connection()
                             ~~~~~~~~~~~~~~~~~~~~~^^
  File "C:\Users\Yakubov\AppData\Local\pypoetry\Cache\virtualenvs\lansweeperdataservice-dSLrnmG5-py3.13\Lib\site-packages\sqlalchemy\engine\base.py", line 3297, in raw_connection
    return self.pool.connect()
           ~~~~~~~~~~~~~~~~~^^
  File "C:\Users\Yakubov\AppData\Local\pypoetry\Cache\virtualenvs\lansweeperdataservice-dSLrnmG5-py3.13\Lib\site-packages\sqlalchemy\pool\base.py", line 449, in connect
    return _ConnectionFairy._checkout(self)
           ~~~~~~~~~~~~~~~~~~~~~~~~~~^^^^^^
  File "C:\Users\Yakubov\AppData\Local\pypoetry\Cache\virtualenvs\lansweeperdataservice-dSLrnmG5-py3.13\Lib\site-packages\sqlalchemy\pool\base.py", line 1264, in _checkout
    fairy = _ConnectionRecord.checkout(pool)
  File "C:\Users\Yakubov\AppData\Local\pypoetry\Cache\virtualenvs\lansweeperdataservice-dSLrnmG5-py3.13\Lib\site-packages\sqlalchemy\pool\base.py", line 713, in checkout
    rec = pool._do_get()
  File "C:\Users\Yakubov\AppData\Local\pypoetry\Cache\virtualenvs\lansweeperdataservice-dSLrnmG5-py3.13\Lib\site-packages\sqlalchemy\pool\impl.py", line 179, in _do_get
    with util.safe_reraise():
         ~~~~~~~~~~~~~~~~~^^
  File "C:\Users\Yakubov\AppData\Local\pypoetry\Cache\virtualenvs\lansweeperdataservice-dSLrnmG5-py3.13\Lib\site-packages\sqlalchemy\util\langhelpers.py", line 224, in __exit__
    raise exc_value.with_traceback(exc_tb)
  File "C:\Users\Yakubov\AppData\Local\pypoetry\Cache\virtualenvs\lansweeperdataservice-dSLrnmG5-py3.13\Lib\site-packages\sqlalchemy\pool\impl.py", line 177, in _do_get
    return self._create_connection()
           ~~~~~~~~~~~~~~~~~~~~~~~^^
  File "C:\Users\Yakubov\AppData\Local\pypoetry\Cache\virtualenvs\lansweeperdataservice-dSLrnmG5-py3.13\Lib\site-packages\sqlalchemy\pool\base.py", line 390, in _create_connection
    return _ConnectionRecord(self)
  File "C:\Users\Yakubov\AppData\Local\pypoetry\Cache\virtualenvs\lansweeperdataservice-dSLrnmG5-py3.13\Lib\site-packages\sqlalchemy\pool\base.py", line 675, in __init__
    self.__connect()
    ~~~~~~~~~~~~~~^^
  File "C:\Users\Yakubov\AppData\Local\pypoetry\Cache\virtualenvs\lansweeperdataservice-dSLrnmG5-py3.13\Lib\site-packages\sqlalchemy\pool\base.py", line 901, in __connect
    with util.safe_reraise():
         ~~~~~~~~~~~~~~~~~^^
  File "C:\Users\Yakubov\AppData\Local\pypoetry\Cache\virtualenvs\lansweeperdataservice-dSLrnmG5-py3.13\Lib\site-packages\sqlalchemy\util\langhelpers.py", line 224, in __exit__
    raise exc_value.with_traceback(exc_tb)
  File "C:\Users\Yakubov\AppData\Local\pypoetry\Cache\virtualenvs\lansweeperdataservice-dSLrnmG5-py3.13\Lib\site-packages\sqlalchemy\pool\base.py", line 897, in __connect
    self.dbapi_connection = connection = pool._invoke_creator(self)
                                         ~~~~~~~~~~~~~~~~~~~~^^^^^^
  File "C:\Users\Yakubov\AppData\Local\pypoetry\Cache\virtualenvs\lansweeperdataservice-dSLrnmG5-py3.13\Lib\site-packages\sqlalchemy\engine\create.py", line 646, in connect
    return dialect.connect(*cargs, **cparams)
           ~~~~~~~~~~~~~~~^^^^^^^^^^^^^^^^^^^
  File "C:\Users\Yakubov\AppData\Local\pypoetry\Cache\virtualenvs\lansweeperdataservice-dSLrnmG5-py3.13\Lib\site-packages\sqlalchemy\engine\default.py", line 625, in connect
    return self.loaded_dbapi.connect(*cargs, **cparams)  # type: ignore[no-any-return]  # NOQA: E501
           ~~~~~~~~~~~~~~~~~~~~~~~~~^^^^^^^^^^^^^^^^^^^
  File "C:\Users\Yakubov\AppData\Local\pypoetry\Cache\virtualenvs\lansweeperdataservice-dSLrnmG5-py3.13\Lib\site-packages\sqlalchemy\dialects\postgresql\asyncpg.py", line 961, in connect
    await_only(creator_fn(*arg, **kw)),
               ~~~~~~~~~~^^^^^^^^^^^^
TypeError: connect() got an unexpected keyword argument 'client_encoding'
2025-08-15 18:05:31,931 ERROR Unclosed connection
connection: <aioodbc.connection.Connection object at 0x00000160DC5957F0>
2025-08-15 18:07:25,797 INFO API server STARTED
2025-08-15 18:07:25,797 INFO Start base migration
2025-08-15 18:07:35,515 INFO API - handle /start-sync request
2025-08-15 18:07:35,518 INFO START
2025-08-15 18:07:35,632 INFO START Synchronization..
2025-08-15 18:07:35,647 ERROR Error during database select operation: (pyodbc.InterfaceError) ('IM002', '[IM002] [Microsoft][ODBC Driver Manager] Data source name not found and no default driver specified (0) (SQLDriverConnect); [IM002] [Microsoft][ODBC Driver Manager] Invalid connection string attribute (0)')
(Background on this error at: https://sqlalche.me/e/20/rvf5)
Traceback (most recent call last):
  File "C:\Users\Yakubov\AppData\Local\pypoetry\Cache\virtualenvs\lansweeperdataservice-dSLrnmG5-py3.13\Lib\site-packages\sqlalchemy\engine\base.py", line 145, in __init__
    self._dbapi_connection = engine.raw_connection()
                             ~~~~~~~~~~~~~~~~~~~~~^^
  File "C:\Users\Yakubov\AppData\Local\pypoetry\Cache\virtualenvs\lansweeperdataservice-dSLrnmG5-py3.13\Lib\site-packages\sqlalchemy\engine\base.py", line 3297, in raw_connection
    return self.pool.connect()
           ~~~~~~~~~~~~~~~~~^^
  File "C:\Users\Yakubov\AppData\Local\pypoetry\Cache\virtualenvs\lansweeperdataservice-dSLrnmG5-py3.13\Lib\site-packages\sqlalchemy\pool\base.py", line 449, in connect
    return _ConnectionFairy._checkout(self)
           ~~~~~~~~~~~~~~~~~~~~~~~~~~^^^^^^
  File "C:\Users\Yakubov\AppData\Local\pypoetry\Cache\virtualenvs\lansweeperdataservice-dSLrnmG5-py3.13\Lib\site-packages\sqlalchemy\pool\base.py", line 1264, in _checkout
    fairy = _ConnectionRecord.checkout(pool)
  File "C:\Users\Yakubov\AppData\Local\pypoetry\Cache\virtualenvs\lansweeperdataservice-dSLrnmG5-py3.13\Lib\site-packages\sqlalchemy\pool\base.py", line 713, in checkout
    rec = pool._do_get()
  File "C:\Users\Yakubov\AppData\Local\pypoetry\Cache\virtualenvs\lansweeperdataservice-dSLrnmG5-py3.13\Lib\site-packages\sqlalchemy\pool\impl.py", line 179, in _do_get
    with util.safe_reraise():
         ~~~~~~~~~~~~~~~~~^^
  File "C:\Users\Yakubov\AppData\Local\pypoetry\Cache\virtualenvs\lansweeperdataservice-dSLrnmG5-py3.13\Lib\site-packages\sqlalchemy\util\langhelpers.py", line 224, in __exit__
    raise exc_value.with_traceback(exc_tb)
  File "C:\Users\Yakubov\AppData\Local\pypoetry\Cache\virtualenvs\lansweeperdataservice-dSLrnmG5-py3.13\Lib\site-packages\sqlalchemy\pool\impl.py", line 177, in _do_get
    return self._create_connection()
           ~~~~~~~~~~~~~~~~~~~~~~~^^
  File "C:\Users\Yakubov\AppData\Local\pypoetry\Cache\virtualenvs\lansweeperdataservice-dSLrnmG5-py3.13\Lib\site-packages\sqlalchemy\pool\base.py", line 390, in _create_connection
    return _ConnectionRecord(self)
  File "C:\Users\Yakubov\AppData\Local\pypoetry\Cache\virtualenvs\lansweeperdataservice-dSLrnmG5-py3.13\Lib\site-packages\sqlalchemy\pool\base.py", line 675, in __init__
    self.__connect()
    ~~~~~~~~~~~~~~^^
  File "C:\Users\Yakubov\AppData\Local\pypoetry\Cache\virtualenvs\lansweeperdataservice-dSLrnmG5-py3.13\Lib\site-packages\sqlalchemy\pool\base.py", line 901, in __connect
    with util.safe_reraise():
         ~~~~~~~~~~~~~~~~~^^
  File "C:\Users\Yakubov\AppData\Local\pypoetry\Cache\virtualenvs\lansweeperdataservice-dSLrnmG5-py3.13\Lib\site-packages\sqlalchemy\util\langhelpers.py", line 224, in __exit__
    raise exc_value.with_traceback(exc_tb)
  File "C:\Users\Yakubov\AppData\Local\pypoetry\Cache\virtualenvs\lansweeperdataservice-dSLrnmG5-py3.13\Lib\site-packages\sqlalchemy\pool\base.py", line 897, in __connect
    self.dbapi_connection = connection = pool._invoke_creator(self)
                                         ~~~~~~~~~~~~~~~~~~~~^^^^^^
  File "C:\Users\Yakubov\AppData\Local\pypoetry\Cache\virtualenvs\lansweeperdataservice-dSLrnmG5-py3.13\Lib\site-packages\sqlalchemy\engine\create.py", line 646, in connect
    return dialect.connect(*cargs, **cparams)
           ~~~~~~~~~~~~~~~^^^^^^^^^^^^^^^^^^^
  File "C:\Users\Yakubov\AppData\Local\pypoetry\Cache\virtualenvs\lansweeperdataservice-dSLrnmG5-py3.13\Lib\site-packages\sqlalchemy\engine\default.py", line 625, in connect
    return self.loaded_dbapi.connect(*cargs, **cparams)  # type: ignore[no-any-return]  # NOQA: E501
           ~~~~~~~~~~~~~~~~~~~~~~~~~^^^^^^^^^^^^^^^^^^^
  File "C:\Users\Yakubov\AppData\Local\pypoetry\Cache\virtualenvs\lansweeperdataservice-dSLrnmG5-py3.13\Lib\site-packages\sqlalchemy\connectors\aioodbc.py", line 141, in connect
    await_only(creator_fn(*arg, **kw)),
    ~~~~~~~~~~^^^^^^^^^^^^^^^^^^^^^^^^
  File "C:\Users\Yakubov\AppData\Local\pypoetry\Cache\virtualenvs\lansweeperdataservice-dSLrnmG5-py3.13\Lib\site-packages\sqlalchemy\util\_concurrency_py3k.py", line 132, in await_only
    return current.parent.switch(awaitable)  # type: ignore[no-any-return,attr-defined] # noqa: E501
           ~~~~~~~~~~~~~~~~~~~~~^^^^^^^^^^^
  File "C:\Users\Yakubov\AppData\Local\pypoetry\Cache\virtualenvs\lansweeperdataservice-dSLrnmG5-py3.13\Lib\site-packages\sqlalchemy\util\_concurrency_py3k.py", line 196, in greenlet_spawn
    value = await result
            ^^^^^^^^^^^^
  File "C:\Users\Yakubov\AppData\Local\pypoetry\Cache\virtualenvs\lansweeperdataservice-dSLrnmG5-py3.13\Lib\site-packages\aioodbc\connection.py", line 277, in _connect
    await conn._connect()
  File "C:\Users\Yakubov\AppData\Local\pypoetry\Cache\virtualenvs\lansweeperdataservice-dSLrnmG5-py3.13\Lib\site-packages\aioodbc\connection.py", line 81, in _connect
    self._conn = await f
                 ^^^^^^^
  File "C:\Program Files\Python313\Lib\concurrent\futures\thread.py", line 59, in run
    result = self.fn(*self.args, **self.kwargs)
pyodbc.InterfaceError: ('IM002', '[IM002] [Microsoft][ODBC Driver Manager] Data source name not found and no default driver specified (0) (SQLDriverConnect); [IM002] [Microsoft][ODBC Driver Manager] Invalid connection string attribute (0)')

The above exception was the direct cause of the following exception:

Traceback (most recent call last):
  File "C:\Users\Yakubov\Documents\Development\LansweeperDataService\src\classes\Database.py", line 31, in select
    result = await session.execute(query)
             ^^^^^^^^^^^^^^^^^^^^^^^^^^^^
  File "C:\Users\Yakubov\AppData\Local\pypoetry\Cache\virtualenvs\lansweeperdataservice-dSLrnmG5-py3.13\Lib\site-packages\sqlalchemy\ext\asyncio\session.py", line 463, in execute
    result = await greenlet_spawn(
             ^^^^^^^^^^^^^^^^^^^^^
    ...<6 lines>...
    )
    ^
  File "C:\Users\Yakubov\AppData\Local\pypoetry\Cache\virtualenvs\lansweeperdataservice-dSLrnmG5-py3.13\Lib\site-packages\sqlalchemy\util\_concurrency_py3k.py", line 201, in greenlet_spawn
    result = context.throw(*sys.exc_info())
  File "C:\Users\Yakubov\AppData\Local\pypoetry\Cache\virtualenvs\lansweeperdataservice-dSLrnmG5-py3.13\Lib\site-packages\sqlalchemy\orm\session.py", line 2365, in execute
    return self._execute_internal(
           ~~~~~~~~~~~~~~~~~~~~~~^
        statement,
        ^^^^^^^^^^
    ...<4 lines>...
        _add_event=_add_event,
        ^^^^^^^^^^^^^^^^^^^^^^
    )
    ^
  File "C:\Users\Yakubov\AppData\Local\pypoetry\Cache\virtualenvs\lansweeperdataservice-dSLrnmG5-py3.13\Lib\site-packages\sqlalchemy\orm\session.py", line 2241, in _execute_internal
    conn = self._connection_for_bind(bind)
  File "C:\Users\Yakubov\AppData\Local\pypoetry\Cache\virtualenvs\lansweeperdataservice-dSLrnmG5-py3.13\Lib\site-packages\sqlalchemy\orm\session.py", line 2110, in _connection_for_bind
    return trans._connection_for_bind(engine, execution_options)
           ~~~~~~~~~~~~~~~~~~~~~~~~~~^^^^^^^^^^^^^^^^^^^^^^^^^^^
  File "<string>", line 2, in _connection_for_bind
  File "C:\Users\Yakubov\AppData\Local\pypoetry\Cache\virtualenvs\lansweeperdataservice-dSLrnmG5-py3.13\Lib\site-packages\sqlalchemy\orm\state_changes.py", line 139, in _go
    ret_value = fn(self, *arg, **kw)
  File "C:\Users\Yakubov\AppData\Local\pypoetry\Cache\virtualenvs\lansweeperdataservice-dSLrnmG5-py3.13\Lib\site-packages\sqlalchemy\orm\session.py", line 1189, in _connection_for_bind
    conn = bind.connect()
  File "C:\Users\Yakubov\AppData\Local\pypoetry\Cache\virtualenvs\lansweeperdataservice-dSLrnmG5-py3.13\Lib\site-packages\sqlalchemy\engine\base.py", line 3273, in connect
    return self._connection_cls(self)
           ~~~~~~~~~~~~~~~~~~~~^^^^^^
  File "C:\Users\Yakubov\AppData\Local\pypoetry\Cache\virtualenvs\lansweeperdataservice-dSLrnmG5-py3.13\Lib\site-packages\sqlalchemy\engine\base.py", line 147, in __init__
    Connection._handle_dbapi_exception_noconnection(
    ~~~~~~~~~~~~~~~~~~~~~~~~~~~~~~~~~~~~~~~~~~~~~~~^
        err, dialect, engine
        ^^^^^^^^^^^^^^^^^^^^
    )
    ^
  File "C:\Users\Yakubov\AppData\Local\pypoetry\Cache\virtualenvs\lansweeperdataservice-dSLrnmG5-py3.13\Lib\site-packages\sqlalchemy\engine\base.py", line 2436, in _handle_dbapi_exception_noconnection
    raise sqlalchemy_exception.with_traceback(exc_info[2]) from e
  File "C:\Users\Yakubov\AppData\Local\pypoetry\Cache\virtualenvs\lansweeperdataservice-dSLrnmG5-py3.13\Lib\site-packages\sqlalchemy\engine\base.py", line 145, in __init__
    self._dbapi_connection = engine.raw_connection()
                             ~~~~~~~~~~~~~~~~~~~~~^^
  File "C:\Users\Yakubov\AppData\Local\pypoetry\Cache\virtualenvs\lansweeperdataservice-dSLrnmG5-py3.13\Lib\site-packages\sqlalchemy\engine\base.py", line 3297, in raw_connection
    return self.pool.connect()
           ~~~~~~~~~~~~~~~~~^^
  File "C:\Users\Yakubov\AppData\Local\pypoetry\Cache\virtualenvs\lansweeperdataservice-dSLrnmG5-py3.13\Lib\site-packages\sqlalchemy\pool\base.py", line 449, in connect
    return _ConnectionFairy._checkout(self)
           ~~~~~~~~~~~~~~~~~~~~~~~~~~^^^^^^
  File "C:\Users\Yakubov\AppData\Local\pypoetry\Cache\virtualenvs\lansweeperdataservice-dSLrnmG5-py3.13\Lib\site-packages\sqlalchemy\pool\base.py", line 1264, in _checkout
    fairy = _ConnectionRecord.checkout(pool)
  File "C:\Users\Yakubov\AppData\Local\pypoetry\Cache\virtualenvs\lansweeperdataservice-dSLrnmG5-py3.13\Lib\site-packages\sqlalchemy\pool\base.py", line 713, in checkout
    rec = pool._do_get()
  File "C:\Users\Yakubov\AppData\Local\pypoetry\Cache\virtualenvs\lansweeperdataservice-dSLrnmG5-py3.13\Lib\site-packages\sqlalchemy\pool\impl.py", line 179, in _do_get
    with util.safe_reraise():
         ~~~~~~~~~~~~~~~~~^^
  File "C:\Users\Yakubov\AppData\Local\pypoetry\Cache\virtualenvs\lansweeperdataservice-dSLrnmG5-py3.13\Lib\site-packages\sqlalchemy\util\langhelpers.py", line 224, in __exit__
    raise exc_value.with_traceback(exc_tb)
  File "C:\Users\Yakubov\AppData\Local\pypoetry\Cache\virtualenvs\lansweeperdataservice-dSLrnmG5-py3.13\Lib\site-packages\sqlalchemy\pool\impl.py", line 177, in _do_get
    return self._create_connection()
           ~~~~~~~~~~~~~~~~~~~~~~~^^
  File "C:\Users\Yakubov\AppData\Local\pypoetry\Cache\virtualenvs\lansweeperdataservice-dSLrnmG5-py3.13\Lib\site-packages\sqlalchemy\pool\base.py", line 390, in _create_connection
    return _ConnectionRecord(self)
  File "C:\Users\Yakubov\AppData\Local\pypoetry\Cache\virtualenvs\lansweeperdataservice-dSLrnmG5-py3.13\Lib\site-packages\sqlalchemy\pool\base.py", line 675, in __init__
    self.__connect()
    ~~~~~~~~~~~~~~^^
  File "C:\Users\Yakubov\AppData\Local\pypoetry\Cache\virtualenvs\lansweeperdataservice-dSLrnmG5-py3.13\Lib\site-packages\sqlalchemy\pool\base.py", line 901, in __connect
    with util.safe_reraise():
         ~~~~~~~~~~~~~~~~~^^
  File "C:\Users\Yakubov\AppData\Local\pypoetry\Cache\virtualenvs\lansweeperdataservice-dSLrnmG5-py3.13\Lib\site-packages\sqlalchemy\util\langhelpers.py", line 224, in __exit__
    raise exc_value.with_traceback(exc_tb)
  File "C:\Users\Yakubov\AppData\Local\pypoetry\Cache\virtualenvs\lansweeperdataservice-dSLrnmG5-py3.13\Lib\site-packages\sqlalchemy\pool\base.py", line 897, in __connect
    self.dbapi_connection = connection = pool._invoke_creator(self)
                                         ~~~~~~~~~~~~~~~~~~~~^^^^^^
  File "C:\Users\Yakubov\AppData\Local\pypoetry\Cache\virtualenvs\lansweeperdataservice-dSLrnmG5-py3.13\Lib\site-packages\sqlalchemy\engine\create.py", line 646, in connect
    return dialect.connect(*cargs, **cparams)
           ~~~~~~~~~~~~~~~^^^^^^^^^^^^^^^^^^^
  File "C:\Users\Yakubov\AppData\Local\pypoetry\Cache\virtualenvs\lansweeperdataservice-dSLrnmG5-py3.13\Lib\site-packages\sqlalchemy\engine\default.py", line 625, in connect
    return self.loaded_dbapi.connect(*cargs, **cparams)  # type: ignore[no-any-return]  # NOQA: E501
           ~~~~~~~~~~~~~~~~~~~~~~~~~^^^^^^^^^^^^^^^^^^^
  File "C:\Users\Yakubov\AppData\Local\pypoetry\Cache\virtualenvs\lansweeperdataservice-dSLrnmG5-py3.13\Lib\site-packages\sqlalchemy\connectors\aioodbc.py", line 141, in connect
    await_only(creator_fn(*arg, **kw)),
    ~~~~~~~~~~^^^^^^^^^^^^^^^^^^^^^^^^
  File "C:\Users\Yakubov\AppData\Local\pypoetry\Cache\virtualenvs\lansweeperdataservice-dSLrnmG5-py3.13\Lib\site-packages\sqlalchemy\util\_concurrency_py3k.py", line 132, in await_only
    return current.parent.switch(awaitable)  # type: ignore[no-any-return,attr-defined] # noqa: E501
           ~~~~~~~~~~~~~~~~~~~~~^^^^^^^^^^^
  File "C:\Users\Yakubov\AppData\Local\pypoetry\Cache\virtualenvs\lansweeperdataservice-dSLrnmG5-py3.13\Lib\site-packages\sqlalchemy\util\_concurrency_py3k.py", line 196, in greenlet_spawn
    value = await result
            ^^^^^^^^^^^^
  File "C:\Users\Yakubov\AppData\Local\pypoetry\Cache\virtualenvs\lansweeperdataservice-dSLrnmG5-py3.13\Lib\site-packages\aioodbc\connection.py", line 277, in _connect
    await conn._connect()
  File "C:\Users\Yakubov\AppData\Local\pypoetry\Cache\virtualenvs\lansweeperdataservice-dSLrnmG5-py3.13\Lib\site-packages\aioodbc\connection.py", line 81, in _connect
    self._conn = await f
                 ^^^^^^^
  File "C:\Program Files\Python313\Lib\concurrent\futures\thread.py", line 59, in run
    result = self.fn(*self.args, **self.kwargs)
sqlalchemy.exc.InterfaceError: (pyodbc.InterfaceError) ('IM002', '[IM002] [Microsoft][ODBC Driver Manager] Data source name not found and no default driver specified (0) (SQLDriverConnect); [IM002] [Microsoft][ODBC Driver Manager] Invalid connection string attribute (0)')
(Background on this error at: https://sqlalche.me/e/20/rvf5)
2025-08-15 18:07:35,705 ERROR Synchronization FAILED. In functions/sync_data.py: ('classes/LansweeperDatabase.py -> LansweeperDatabase.get_mapped_custom_names -> ', InterfaceError("(pyodbc.InterfaceError) ('IM002', '[IM002] [Microsoft][ODBC Driver Manager] Data source name not found and no default driver specified (0) (SQLDriverConnect); [IM002] [Microsoft][ODBC Driver Manager] Invalid connection string attribute (0)')"))
2025-08-15 18:07:35,707 ERROR Error during database insert operation: connect() got an unexpected keyword argument 'encoding'
Traceback (most recent call last):
  File "C:\Users\Yakubov\Documents\Development\LansweeperDataService\src\classes\Database.py", line 53, in insert
    await session.execute(insert(table).values(values))
  File "C:\Users\Yakubov\AppData\Local\pypoetry\Cache\virtualenvs\lansweeperdataservice-dSLrnmG5-py3.13\Lib\site-packages\sqlalchemy\ext\asyncio\session.py", line 463, in execute
    result = await greenlet_spawn(
             ^^^^^^^^^^^^^^^^^^^^^
    ...<6 lines>...
    )
    ^
  File "C:\Users\Yakubov\AppData\Local\pypoetry\Cache\virtualenvs\lansweeperdataservice-dSLrnmG5-py3.13\Lib\site-packages\sqlalchemy\util\_concurrency_py3k.py", line 190, in greenlet_spawn
    result = context.switch(*args, **kwargs)
  File "C:\Users\Yakubov\AppData\Local\pypoetry\Cache\virtualenvs\lansweeperdataservice-dSLrnmG5-py3.13\Lib\site-packages\sqlalchemy\orm\session.py", line 2365, in execute
    return self._execute_internal(
           ~~~~~~~~~~~~~~~~~~~~~~^
        statement,
        ^^^^^^^^^^
    ...<4 lines>...
        _add_event=_add_event,
        ^^^^^^^^^^^^^^^^^^^^^^
    )
    ^
  File "C:\Users\Yakubov\AppData\Local\pypoetry\Cache\virtualenvs\lansweeperdataservice-dSLrnmG5-py3.13\Lib\site-packages\sqlalchemy\orm\session.py", line 2241, in _execute_internal
    conn = self._connection_for_bind(bind)
  File "C:\Users\Yakubov\AppData\Local\pypoetry\Cache\virtualenvs\lansweeperdataservice-dSLrnmG5-py3.13\Lib\site-packages\sqlalchemy\orm\session.py", line 2110, in _connection_for_bind
    return trans._connection_for_bind(engine, execution_options)
           ~~~~~~~~~~~~~~~~~~~~~~~~~~^^^^^^^^^^^^^^^^^^^^^^^^^^^
  File "<string>", line 2, in _connection_for_bind
  File "C:\Users\Yakubov\AppData\Local\pypoetry\Cache\virtualenvs\lansweeperdataservice-dSLrnmG5-py3.13\Lib\site-packages\sqlalchemy\orm\state_changes.py", line 139, in _go
    ret_value = fn(self, *arg, **kw)
  File "C:\Users\Yakubov\AppData\Local\pypoetry\Cache\virtualenvs\lansweeperdataservice-dSLrnmG5-py3.13\Lib\site-packages\sqlalchemy\orm\session.py", line 1189, in _connection_for_bind
    conn = bind.connect()
  File "C:\Users\Yakubov\AppData\Local\pypoetry\Cache\virtualenvs\lansweeperdataservice-dSLrnmG5-py3.13\Lib\site-packages\sqlalchemy\engine\base.py", line 3273, in connect
    return self._connection_cls(self)
           ~~~~~~~~~~~~~~~~~~~~^^^^^^
  File "C:\Users\Yakubov\AppData\Local\pypoetry\Cache\virtualenvs\lansweeperdataservice-dSLrnmG5-py3.13\Lib\site-packages\sqlalchemy\engine\base.py", line 145, in __init__
    self._dbapi_connection = engine.raw_connection()
                             ~~~~~~~~~~~~~~~~~~~~~^^
  File "C:\Users\Yakubov\AppData\Local\pypoetry\Cache\virtualenvs\lansweeperdataservice-dSLrnmG5-py3.13\Lib\site-packages\sqlalchemy\engine\base.py", line 3297, in raw_connection
    return self.pool.connect()
           ~~~~~~~~~~~~~~~~~^^
  File "C:\Users\Yakubov\AppData\Local\pypoetry\Cache\virtualenvs\lansweeperdataservice-dSLrnmG5-py3.13\Lib\site-packages\sqlalchemy\pool\base.py", line 449, in connect
    return _ConnectionFairy._checkout(self)
           ~~~~~~~~~~~~~~~~~~~~~~~~~~^^^^^^
  File "C:\Users\Yakubov\AppData\Local\pypoetry\Cache\virtualenvs\lansweeperdataservice-dSLrnmG5-py3.13\Lib\site-packages\sqlalchemy\pool\base.py", line 1264, in _checkout
    fairy = _ConnectionRecord.checkout(pool)
  File "C:\Users\Yakubov\AppData\Local\pypoetry\Cache\virtualenvs\lansweeperdataservice-dSLrnmG5-py3.13\Lib\site-packages\sqlalchemy\pool\base.py", line 713, in checkout
    rec = pool._do_get()
  File "C:\Users\Yakubov\AppData\Local\pypoetry\Cache\virtualenvs\lansweeperdataservice-dSLrnmG5-py3.13\Lib\site-packages\sqlalchemy\pool\impl.py", line 179, in _do_get
    with util.safe_reraise():
         ~~~~~~~~~~~~~~~~~^^
  File "C:\Users\Yakubov\AppData\Local\pypoetry\Cache\virtualenvs\lansweeperdataservice-dSLrnmG5-py3.13\Lib\site-packages\sqlalchemy\util\langhelpers.py", line 224, in __exit__
    raise exc_value.with_traceback(exc_tb)
  File "C:\Users\Yakubov\AppData\Local\pypoetry\Cache\virtualenvs\lansweeperdataservice-dSLrnmG5-py3.13\Lib\site-packages\sqlalchemy\pool\impl.py", line 177, in _do_get
    return self._create_connection()
           ~~~~~~~~~~~~~~~~~~~~~~~^^
  File "C:\Users\Yakubov\AppData\Local\pypoetry\Cache\virtualenvs\lansweeperdataservice-dSLrnmG5-py3.13\Lib\site-packages\sqlalchemy\pool\base.py", line 390, in _create_connection
    return _ConnectionRecord(self)
  File "C:\Users\Yakubov\AppData\Local\pypoetry\Cache\virtualenvs\lansweeperdataservice-dSLrnmG5-py3.13\Lib\site-packages\sqlalchemy\pool\base.py", line 675, in __init__
    self.__connect()
    ~~~~~~~~~~~~~~^^
  File "C:\Users\Yakubov\AppData\Local\pypoetry\Cache\virtualenvs\lansweeperdataservice-dSLrnmG5-py3.13\Lib\site-packages\sqlalchemy\pool\base.py", line 901, in __connect
    with util.safe_reraise():
         ~~~~~~~~~~~~~~~~~^^
  File "C:\Users\Yakubov\AppData\Local\pypoetry\Cache\virtualenvs\lansweeperdataservice-dSLrnmG5-py3.13\Lib\site-packages\sqlalchemy\util\langhelpers.py", line 224, in __exit__
    raise exc_value.with_traceback(exc_tb)
  File "C:\Users\Yakubov\AppData\Local\pypoetry\Cache\virtualenvs\lansweeperdataservice-dSLrnmG5-py3.13\Lib\site-packages\sqlalchemy\pool\base.py", line 897, in __connect
    self.dbapi_connection = connection = pool._invoke_creator(self)
                                         ~~~~~~~~~~~~~~~~~~~~^^^^^^
  File "C:\Users\Yakubov\AppData\Local\pypoetry\Cache\virtualenvs\lansweeperdataservice-dSLrnmG5-py3.13\Lib\site-packages\sqlalchemy\engine\create.py", line 646, in connect
    return dialect.connect(*cargs, **cparams)
           ~~~~~~~~~~~~~~~^^^^^^^^^^^^^^^^^^^
  File "C:\Users\Yakubov\AppData\Local\pypoetry\Cache\virtualenvs\lansweeperdataservice-dSLrnmG5-py3.13\Lib\site-packages\sqlalchemy\engine\default.py", line 625, in connect
    return self.loaded_dbapi.connect(*cargs, **cparams)  # type: ignore[no-any-return]  # NOQA: E501
           ~~~~~~~~~~~~~~~~~~~~~~~~~^^^^^^^^^^^^^^^^^^^
  File "C:\Users\Yakubov\AppData\Local\pypoetry\Cache\virtualenvs\lansweeperdataservice-dSLrnmG5-py3.13\Lib\site-packages\sqlalchemy\dialects\postgresql\asyncpg.py", line 961, in connect
    await_only(creator_fn(*arg, **kw)),
               ~~~~~~~~~~^^^^^^^^^^^^
TypeError: connect() got an unexpected keyword argument 'encoding'
2025-08-15 18:07:35,720 ERROR Synchronization error: connect() got an unexpected keyword argument 'encoding'
Traceback (most recent call last):
  File "C:\Users\Yakubov\Documents\Development\LansweeperDataService\src\sync.py", line 25, in sync
    await service.insert(
    ...<2 lines>...
    )
  File "C:\Users\Yakubov\Documents\Development\LansweeperDataService\src\classes\Database.py", line 58, in insert
    raise e
  File "C:\Users\Yakubov\Documents\Development\LansweeperDataService\src\classes\Database.py", line 53, in insert
    await session.execute(insert(table).values(values))
  File "C:\Users\Yakubov\AppData\Local\pypoetry\Cache\virtualenvs\lansweeperdataservice-dSLrnmG5-py3.13\Lib\site-packages\sqlalchemy\ext\asyncio\session.py", line 463, in execute
    result = await greenlet_spawn(
             ^^^^^^^^^^^^^^^^^^^^^
    ...<6 lines>...
    )
    ^
  File "C:\Users\Yakubov\AppData\Local\pypoetry\Cache\virtualenvs\lansweeperdataservice-dSLrnmG5-py3.13\Lib\site-packages\sqlalchemy\util\_concurrency_py3k.py", line 190, in greenlet_spawn
    result = context.switch(*args, **kwargs)
  File "C:\Users\Yakubov\AppData\Local\pypoetry\Cache\virtualenvs\lansweeperdataservice-dSLrnmG5-py3.13\Lib\site-packages\sqlalchemy\orm\session.py", line 2365, in execute
    return self._execute_internal(
           ~~~~~~~~~~~~~~~~~~~~~~^
        statement,
        ^^^^^^^^^^
    ...<4 lines>...
        _add_event=_add_event,
        ^^^^^^^^^^^^^^^^^^^^^^
    )
    ^
  File "C:\Users\Yakubov\AppData\Local\pypoetry\Cache\virtualenvs\lansweeperdataservice-dSLrnmG5-py3.13\Lib\site-packages\sqlalchemy\orm\session.py", line 2241, in _execute_internal
    conn = self._connection_for_bind(bind)
  File "C:\Users\Yakubov\AppData\Local\pypoetry\Cache\virtualenvs\lansweeperdataservice-dSLrnmG5-py3.13\Lib\site-packages\sqlalchemy\orm\session.py", line 2110, in _connection_for_bind
    return trans._connection_for_bind(engine, execution_options)
           ~~~~~~~~~~~~~~~~~~~~~~~~~~^^^^^^^^^^^^^^^^^^^^^^^^^^^
  File "<string>", line 2, in _connection_for_bind
  File "C:\Users\Yakubov\AppData\Local\pypoetry\Cache\virtualenvs\lansweeperdataservice-dSLrnmG5-py3.13\Lib\site-packages\sqlalchemy\orm\state_changes.py", line 139, in _go
    ret_value = fn(self, *arg, **kw)
  File "C:\Users\Yakubov\AppData\Local\pypoetry\Cache\virtualenvs\lansweeperdataservice-dSLrnmG5-py3.13\Lib\site-packages\sqlalchemy\orm\session.py", line 1189, in _connection_for_bind
    conn = bind.connect()
  File "C:\Users\Yakubov\AppData\Local\pypoetry\Cache\virtualenvs\lansweeperdataservice-dSLrnmG5-py3.13\Lib\site-packages\sqlalchemy\engine\base.py", line 3273, in connect
    return self._connection_cls(self)
           ~~~~~~~~~~~~~~~~~~~~^^^^^^
  File "C:\Users\Yakubov\AppData\Local\pypoetry\Cache\virtualenvs\lansweeperdataservice-dSLrnmG5-py3.13\Lib\site-packages\sqlalchemy\engine\base.py", line 145, in __init__
    self._dbapi_connection = engine.raw_connection()
                             ~~~~~~~~~~~~~~~~~~~~~^^
  File "C:\Users\Yakubov\AppData\Local\pypoetry\Cache\virtualenvs\lansweeperdataservice-dSLrnmG5-py3.13\Lib\site-packages\sqlalchemy\engine\base.py", line 3297, in raw_connection
    return self.pool.connect()
           ~~~~~~~~~~~~~~~~~^^
  File "C:\Users\Yakubov\AppData\Local\pypoetry\Cache\virtualenvs\lansweeperdataservice-dSLrnmG5-py3.13\Lib\site-packages\sqlalchemy\pool\base.py", line 449, in connect
    return _ConnectionFairy._checkout(self)
           ~~~~~~~~~~~~~~~~~~~~~~~~~~^^^^^^
  File "C:\Users\Yakubov\AppData\Local\pypoetry\Cache\virtualenvs\lansweeperdataservice-dSLrnmG5-py3.13\Lib\site-packages\sqlalchemy\pool\base.py", line 1264, in _checkout
    fairy = _ConnectionRecord.checkout(pool)
  File "C:\Users\Yakubov\AppData\Local\pypoetry\Cache\virtualenvs\lansweeperdataservice-dSLrnmG5-py3.13\Lib\site-packages\sqlalchemy\pool\base.py", line 713, in checkout
    rec = pool._do_get()
  File "C:\Users\Yakubov\AppData\Local\pypoetry\Cache\virtualenvs\lansweeperdataservice-dSLrnmG5-py3.13\Lib\site-packages\sqlalchemy\pool\impl.py", line 179, in _do_get
    with util.safe_reraise():
         ~~~~~~~~~~~~~~~~~^^
  File "C:\Users\Yakubov\AppData\Local\pypoetry\Cache\virtualenvs\lansweeperdataservice-dSLrnmG5-py3.13\Lib\site-packages\sqlalchemy\util\langhelpers.py", line 224, in __exit__
    raise exc_value.with_traceback(exc_tb)
  File "C:\Users\Yakubov\AppData\Local\pypoetry\Cache\virtualenvs\lansweeperdataservice-dSLrnmG5-py3.13\Lib\site-packages\sqlalchemy\pool\impl.py", line 177, in _do_get
    return self._create_connection()
           ~~~~~~~~~~~~~~~~~~~~~~~^^
  File "C:\Users\Yakubov\AppData\Local\pypoetry\Cache\virtualenvs\lansweeperdataservice-dSLrnmG5-py3.13\Lib\site-packages\sqlalchemy\pool\base.py", line 390, in _create_connection
    return _ConnectionRecord(self)
  File "C:\Users\Yakubov\AppData\Local\pypoetry\Cache\virtualenvs\lansweeperdataservice-dSLrnmG5-py3.13\Lib\site-packages\sqlalchemy\pool\base.py", line 675, in __init__
    self.__connect()
    ~~~~~~~~~~~~~~^^
  File "C:\Users\Yakubov\AppData\Local\pypoetry\Cache\virtualenvs\lansweeperdataservice-dSLrnmG5-py3.13\Lib\site-packages\sqlalchemy\pool\base.py", line 901, in __connect
    with util.safe_reraise():
         ~~~~~~~~~~~~~~~~~^^
  File "C:\Users\Yakubov\AppData\Local\pypoetry\Cache\virtualenvs\lansweeperdataservice-dSLrnmG5-py3.13\Lib\site-packages\sqlalchemy\util\langhelpers.py", line 224, in __exit__
    raise exc_value.with_traceback(exc_tb)
  File "C:\Users\Yakubov\AppData\Local\pypoetry\Cache\virtualenvs\lansweeperdataservice-dSLrnmG5-py3.13\Lib\site-packages\sqlalchemy\pool\base.py", line 897, in __connect
    self.dbapi_connection = connection = pool._invoke_creator(self)
                                         ~~~~~~~~~~~~~~~~~~~~^^^^^^
  File "C:\Users\Yakubov\AppData\Local\pypoetry\Cache\virtualenvs\lansweeperdataservice-dSLrnmG5-py3.13\Lib\site-packages\sqlalchemy\engine\create.py", line 646, in connect
    return dialect.connect(*cargs, **cparams)
           ~~~~~~~~~~~~~~~^^^^^^^^^^^^^^^^^^^
  File "C:\Users\Yakubov\AppData\Local\pypoetry\Cache\virtualenvs\lansweeperdataservice-dSLrnmG5-py3.13\Lib\site-packages\sqlalchemy\engine\default.py", line 625, in connect
    return self.loaded_dbapi.connect(*cargs, **cparams)  # type: ignore[no-any-return]  # NOQA: E501
           ~~~~~~~~~~~~~~~~~~~~~~~~~^^^^^^^^^^^^^^^^^^^
  File "C:\Users\Yakubov\AppData\Local\pypoetry\Cache\virtualenvs\lansweeperdataservice-dSLrnmG5-py3.13\Lib\site-packages\sqlalchemy\dialects\postgresql\asyncpg.py", line 961, in connect
    await_only(creator_fn(*arg, **kw)),
               ~~~~~~~~~~^^^^^^^^^^^^
TypeError: connect() got an unexpected keyword argument 'encoding'
2025-08-15 18:07:35,731 INFO END
2025-08-15 18:07:35,732 ERROR Task exception was never retrieved
future: <Task finished name='Task-5' coro=<sync() done, defined at C:\Users\Yakubov\Documents\Development\LansweeperDataService\src\sync.py:12> exception=TypeError("connect() got an unexpected keyword argument 'encoding'")>
Traceback (most recent call last):
  File "C:\Users\Yakubov\Documents\Development\LansweeperDataService\src\sync.py", line 32, in sync
    raise e
  File "C:\Users\Yakubov\Documents\Development\LansweeperDataService\src\sync.py", line 25, in sync
    await service.insert(
    ...<2 lines>...
    )
  File "C:\Users\Yakubov\Documents\Development\LansweeperDataService\src\classes\Database.py", line 58, in insert
    raise e
  File "C:\Users\Yakubov\Documents\Development\LansweeperDataService\src\classes\Database.py", line 53, in insert
    await session.execute(insert(table).values(values))
  File "C:\Users\Yakubov\AppData\Local\pypoetry\Cache\virtualenvs\lansweeperdataservice-dSLrnmG5-py3.13\Lib\site-packages\sqlalchemy\ext\asyncio\session.py", line 463, in execute
    result = await greenlet_spawn(
             ^^^^^^^^^^^^^^^^^^^^^
    ...<6 lines>...
    )
    ^
  File "C:\Users\Yakubov\AppData\Local\pypoetry\Cache\virtualenvs\lansweeperdataservice-dSLrnmG5-py3.13\Lib\site-packages\sqlalchemy\util\_concurrency_py3k.py", line 190, in greenlet_spawn
    result = context.switch(*args, **kwargs)
  File "C:\Users\Yakubov\AppData\Local\pypoetry\Cache\virtualenvs\lansweeperdataservice-dSLrnmG5-py3.13\Lib\site-packages\sqlalchemy\orm\session.py", line 2365, in execute
    return self._execute_internal(
           ~~~~~~~~~~~~~~~~~~~~~~^
        statement,
        ^^^^^^^^^^
    ...<4 lines>...
        _add_event=_add_event,
        ^^^^^^^^^^^^^^^^^^^^^^
    )
    ^
  File "C:\Users\Yakubov\AppData\Local\pypoetry\Cache\virtualenvs\lansweeperdataservice-dSLrnmG5-py3.13\Lib\site-packages\sqlalchemy\orm\session.py", line 2241, in _execute_internal
    conn = self._connection_for_bind(bind)
  File "C:\Users\Yakubov\AppData\Local\pypoetry\Cache\virtualenvs\lansweeperdataservice-dSLrnmG5-py3.13\Lib\site-packages\sqlalchemy\orm\session.py", line 2110, in _connection_for_bind
    return trans._connection_for_bind(engine, execution_options)
           ~~~~~~~~~~~~~~~~~~~~~~~~~~^^^^^^^^^^^^^^^^^^^^^^^^^^^
  File "<string>", line 2, in _connection_for_bind
  File "C:\Users\Yakubov\AppData\Local\pypoetry\Cache\virtualenvs\lansweeperdataservice-dSLrnmG5-py3.13\Lib\site-packages\sqlalchemy\orm\state_changes.py", line 139, in _go
    ret_value = fn(self, *arg, **kw)
  File "C:\Users\Yakubov\AppData\Local\pypoetry\Cache\virtualenvs\lansweeperdataservice-dSLrnmG5-py3.13\Lib\site-packages\sqlalchemy\orm\session.py", line 1189, in _connection_for_bind
    conn = bind.connect()
  File "C:\Users\Yakubov\AppData\Local\pypoetry\Cache\virtualenvs\lansweeperdataservice-dSLrnmG5-py3.13\Lib\site-packages\sqlalchemy\engine\base.py", line 3273, in connect
    return self._connection_cls(self)
           ~~~~~~~~~~~~~~~~~~~~^^^^^^
  File "C:\Users\Yakubov\AppData\Local\pypoetry\Cache\virtualenvs\lansweeperdataservice-dSLrnmG5-py3.13\Lib\site-packages\sqlalchemy\engine\base.py", line 145, in __init__
    self._dbapi_connection = engine.raw_connection()
                             ~~~~~~~~~~~~~~~~~~~~~^^
  File "C:\Users\Yakubov\AppData\Local\pypoetry\Cache\virtualenvs\lansweeperdataservice-dSLrnmG5-py3.13\Lib\site-packages\sqlalchemy\engine\base.py", line 3297, in raw_connection
    return self.pool.connect()
           ~~~~~~~~~~~~~~~~~^^
  File "C:\Users\Yakubov\AppData\Local\pypoetry\Cache\virtualenvs\lansweeperdataservice-dSLrnmG5-py3.13\Lib\site-packages\sqlalchemy\pool\base.py", line 449, in connect
    return _ConnectionFairy._checkout(self)
           ~~~~~~~~~~~~~~~~~~~~~~~~~~^^^^^^
  File "C:\Users\Yakubov\AppData\Local\pypoetry\Cache\virtualenvs\lansweeperdataservice-dSLrnmG5-py3.13\Lib\site-packages\sqlalchemy\pool\base.py", line 1264, in _checkout
    fairy = _ConnectionRecord.checkout(pool)
  File "C:\Users\Yakubov\AppData\Local\pypoetry\Cache\virtualenvs\lansweeperdataservice-dSLrnmG5-py3.13\Lib\site-packages\sqlalchemy\pool\base.py", line 713, in checkout
    rec = pool._do_get()
  File "C:\Users\Yakubov\AppData\Local\pypoetry\Cache\virtualenvs\lansweeperdataservice-dSLrnmG5-py3.13\Lib\site-packages\sqlalchemy\pool\impl.py", line 179, in _do_get
    with util.safe_reraise():
         ~~~~~~~~~~~~~~~~~^^
  File "C:\Users\Yakubov\AppData\Local\pypoetry\Cache\virtualenvs\lansweeperdataservice-dSLrnmG5-py3.13\Lib\site-packages\sqlalchemy\util\langhelpers.py", line 224, in __exit__
    raise exc_value.with_traceback(exc_tb)
  File "C:\Users\Yakubov\AppData\Local\pypoetry\Cache\virtualenvs\lansweeperdataservice-dSLrnmG5-py3.13\Lib\site-packages\sqlalchemy\pool\impl.py", line 177, in _do_get
    return self._create_connection()
           ~~~~~~~~~~~~~~~~~~~~~~~^^
  File "C:\Users\Yakubov\AppData\Local\pypoetry\Cache\virtualenvs\lansweeperdataservice-dSLrnmG5-py3.13\Lib\site-packages\sqlalchemy\pool\base.py", line 390, in _create_connection
    return _ConnectionRecord(self)
  File "C:\Users\Yakubov\AppData\Local\pypoetry\Cache\virtualenvs\lansweeperdataservice-dSLrnmG5-py3.13\Lib\site-packages\sqlalchemy\pool\base.py", line 675, in __init__
    self.__connect()
    ~~~~~~~~~~~~~~^^
  File "C:\Users\Yakubov\AppData\Local\pypoetry\Cache\virtualenvs\lansweeperdataservice-dSLrnmG5-py3.13\Lib\site-packages\sqlalchemy\pool\base.py", line 901, in __connect
    with util.safe_reraise():
         ~~~~~~~~~~~~~~~~~^^
  File "C:\Users\Yakubov\AppData\Local\pypoetry\Cache\virtualenvs\lansweeperdataservice-dSLrnmG5-py3.13\Lib\site-packages\sqlalchemy\util\langhelpers.py", line 224, in __exit__
    raise exc_value.with_traceback(exc_tb)
  File "C:\Users\Yakubov\AppData\Local\pypoetry\Cache\virtualenvs\lansweeperdataservice-dSLrnmG5-py3.13\Lib\site-packages\sqlalchemy\pool\base.py", line 897, in __connect
    self.dbapi_connection = connection = pool._invoke_creator(self)
                                         ~~~~~~~~~~~~~~~~~~~~^^^^^^
  File "C:\Users\Yakubov\AppData\Local\pypoetry\Cache\virtualenvs\lansweeperdataservice-dSLrnmG5-py3.13\Lib\site-packages\sqlalchemy\engine\create.py", line 646, in connect
    return dialect.connect(*cargs, **cparams)
           ~~~~~~~~~~~~~~~^^^^^^^^^^^^^^^^^^^
  File "C:\Users\Yakubov\AppData\Local\pypoetry\Cache\virtualenvs\lansweeperdataservice-dSLrnmG5-py3.13\Lib\site-packages\sqlalchemy\engine\default.py", line 625, in connect
    return self.loaded_dbapi.connect(*cargs, **cparams)  # type: ignore[no-any-return]  # NOQA: E501
           ~~~~~~~~~~~~~~~~~~~~~~~~~^^^^^^^^^^^^^^^^^^^
  File "C:\Users\Yakubov\AppData\Local\pypoetry\Cache\virtualenvs\lansweeperdataservice-dSLrnmG5-py3.13\Lib\site-packages\sqlalchemy\dialects\postgresql\asyncpg.py", line 961, in connect
    await_only(creator_fn(*arg, **kw)),
               ~~~~~~~~~~^^^^^^^^^^^^
TypeError: connect() got an unexpected keyword argument 'encoding'
2025-08-15 18:09:31,144 INFO API server STARTED
2025-08-15 18:09:31,145 INFO Start base migration
2025-08-15 18:09:35,867 INFO API - handle /start-sync request
2025-08-15 18:09:35,869 INFO START
2025-08-15 18:09:35,978 INFO START Synchronization..
2025-08-15 18:09:36,828 ERROR Error during database select operation: connect() got an unexpected keyword argument 'client_encoding'
Traceback (most recent call last):
  File "C:\Users\Yakubov\Documents\Development\LansweeperDataService\src\classes\Database.py", line 31, in select
    result = await session.execute(query)
             ^^^^^^^^^^^^^^^^^^^^^^^^^^^^
  File "C:\Users\Yakubov\AppData\Local\pypoetry\Cache\virtualenvs\lansweeperdataservice-dSLrnmG5-py3.13\Lib\site-packages\sqlalchemy\ext\asyncio\session.py", line 463, in execute
    result = await greenlet_spawn(
             ^^^^^^^^^^^^^^^^^^^^^
    ...<6 lines>...
    )
    ^
  File "C:\Users\Yakubov\AppData\Local\pypoetry\Cache\virtualenvs\lansweeperdataservice-dSLrnmG5-py3.13\Lib\site-packages\sqlalchemy\util\_concurrency_py3k.py", line 190, in greenlet_spawn
    result = context.switch(*args, **kwargs)
  File "C:\Users\Yakubov\AppData\Local\pypoetry\Cache\virtualenvs\lansweeperdataservice-dSLrnmG5-py3.13\Lib\site-packages\sqlalchemy\orm\session.py", line 2365, in execute
    return self._execute_internal(
           ~~~~~~~~~~~~~~~~~~~~~~^
        statement,
        ^^^^^^^^^^
    ...<4 lines>...
        _add_event=_add_event,
        ^^^^^^^^^^^^^^^^^^^^^^
    )
    ^
  File "C:\Users\Yakubov\AppData\Local\pypoetry\Cache\virtualenvs\lansweeperdataservice-dSLrnmG5-py3.13\Lib\site-packages\sqlalchemy\orm\session.py", line 2241, in _execute_internal
    conn = self._connection_for_bind(bind)
  File "C:\Users\Yakubov\AppData\Local\pypoetry\Cache\virtualenvs\lansweeperdataservice-dSLrnmG5-py3.13\Lib\site-packages\sqlalchemy\orm\session.py", line 2110, in _connection_for_bind
    return trans._connection_for_bind(engine, execution_options)
           ~~~~~~~~~~~~~~~~~~~~~~~~~~^^^^^^^^^^^^^^^^^^^^^^^^^^^
  File "<string>", line 2, in _connection_for_bind
  File "C:\Users\Yakubov\AppData\Local\pypoetry\Cache\virtualenvs\lansweeperdataservice-dSLrnmG5-py3.13\Lib\site-packages\sqlalchemy\orm\state_changes.py", line 139, in _go
    ret_value = fn(self, *arg, **kw)
  File "C:\Users\Yakubov\AppData\Local\pypoetry\Cache\virtualenvs\lansweeperdataservice-dSLrnmG5-py3.13\Lib\site-packages\sqlalchemy\orm\session.py", line 1189, in _connection_for_bind
    conn = bind.connect()
  File "C:\Users\Yakubov\AppData\Local\pypoetry\Cache\virtualenvs\lansweeperdataservice-dSLrnmG5-py3.13\Lib\site-packages\sqlalchemy\engine\base.py", line 3273, in connect
    return self._connection_cls(self)
           ~~~~~~~~~~~~~~~~~~~~^^^^^^
  File "C:\Users\Yakubov\AppData\Local\pypoetry\Cache\virtualenvs\lansweeperdataservice-dSLrnmG5-py3.13\Lib\site-packages\sqlalchemy\engine\base.py", line 145, in __init__
    self._dbapi_connection = engine.raw_connection()
                             ~~~~~~~~~~~~~~~~~~~~~^^
  File "C:\Users\Yakubov\AppData\Local\pypoetry\Cache\virtualenvs\lansweeperdataservice-dSLrnmG5-py3.13\Lib\site-packages\sqlalchemy\engine\base.py", line 3297, in raw_connection
    return self.pool.connect()
           ~~~~~~~~~~~~~~~~~^^
  File "C:\Users\Yakubov\AppData\Local\pypoetry\Cache\virtualenvs\lansweeperdataservice-dSLrnmG5-py3.13\Lib\site-packages\sqlalchemy\pool\base.py", line 449, in connect
    return _ConnectionFairy._checkout(self)
           ~~~~~~~~~~~~~~~~~~~~~~~~~~^^^^^^
  File "C:\Users\Yakubov\AppData\Local\pypoetry\Cache\virtualenvs\lansweeperdataservice-dSLrnmG5-py3.13\Lib\site-packages\sqlalchemy\pool\base.py", line 1264, in _checkout
    fairy = _ConnectionRecord.checkout(pool)
  File "C:\Users\Yakubov\AppData\Local\pypoetry\Cache\virtualenvs\lansweeperdataservice-dSLrnmG5-py3.13\Lib\site-packages\sqlalchemy\pool\base.py", line 713, in checkout
    rec = pool._do_get()
  File "C:\Users\Yakubov\AppData\Local\pypoetry\Cache\virtualenvs\lansweeperdataservice-dSLrnmG5-py3.13\Lib\site-packages\sqlalchemy\pool\impl.py", line 179, in _do_get
    with util.safe_reraise():
         ~~~~~~~~~~~~~~~~~^^
  File "C:\Users\Yakubov\AppData\Local\pypoetry\Cache\virtualenvs\lansweeperdataservice-dSLrnmG5-py3.13\Lib\site-packages\sqlalchemy\util\langhelpers.py", line 224, in __exit__
    raise exc_value.with_traceback(exc_tb)
  File "C:\Users\Yakubov\AppData\Local\pypoetry\Cache\virtualenvs\lansweeperdataservice-dSLrnmG5-py3.13\Lib\site-packages\sqlalchemy\pool\impl.py", line 177, in _do_get
    return self._create_connection()
           ~~~~~~~~~~~~~~~~~~~~~~~^^
  File "C:\Users\Yakubov\AppData\Local\pypoetry\Cache\virtualenvs\lansweeperdataservice-dSLrnmG5-py3.13\Lib\site-packages\sqlalchemy\pool\base.py", line 390, in _create_connection
    return _ConnectionRecord(self)
  File "C:\Users\Yakubov\AppData\Local\pypoetry\Cache\virtualenvs\lansweeperdataservice-dSLrnmG5-py3.13\Lib\site-packages\sqlalchemy\pool\base.py", line 675, in __init__
    self.__connect()
    ~~~~~~~~~~~~~~^^
  File "C:\Users\Yakubov\AppData\Local\pypoetry\Cache\virtualenvs\lansweeperdataservice-dSLrnmG5-py3.13\Lib\site-packages\sqlalchemy\pool\base.py", line 901, in __connect
    with util.safe_reraise():
         ~~~~~~~~~~~~~~~~~^^
  File "C:\Users\Yakubov\AppData\Local\pypoetry\Cache\virtualenvs\lansweeperdataservice-dSLrnmG5-py3.13\Lib\site-packages\sqlalchemy\util\langhelpers.py", line 224, in __exit__
    raise exc_value.with_traceback(exc_tb)
  File "C:\Users\Yakubov\AppData\Local\pypoetry\Cache\virtualenvs\lansweeperdataservice-dSLrnmG5-py3.13\Lib\site-packages\sqlalchemy\pool\base.py", line 897, in __connect
    self.dbapi_connection = connection = pool._invoke_creator(self)
                                         ~~~~~~~~~~~~~~~~~~~~^^^^^^
  File "C:\Users\Yakubov\AppData\Local\pypoetry\Cache\virtualenvs\lansweeperdataservice-dSLrnmG5-py3.13\Lib\site-packages\sqlalchemy\engine\create.py", line 646, in connect
    return dialect.connect(*cargs, **cparams)
           ~~~~~~~~~~~~~~~^^^^^^^^^^^^^^^^^^^
  File "C:\Users\Yakubov\AppData\Local\pypoetry\Cache\virtualenvs\lansweeperdataservice-dSLrnmG5-py3.13\Lib\site-packages\sqlalchemy\engine\default.py", line 625, in connect
    return self.loaded_dbapi.connect(*cargs, **cparams)  # type: ignore[no-any-return]  # NOQA: E501
           ~~~~~~~~~~~~~~~~~~~~~~~~~^^^^^^^^^^^^^^^^^^^
  File "C:\Users\Yakubov\AppData\Local\pypoetry\Cache\virtualenvs\lansweeperdataservice-dSLrnmG5-py3.13\Lib\site-packages\sqlalchemy\dialects\postgresql\asyncpg.py", line 961, in connect
    await_only(creator_fn(*arg, **kw)),
               ~~~~~~~~~~^^^^^^^^^^^^
TypeError: connect() got an unexpected keyword argument 'client_encoding'
2025-08-15 18:09:36,849 ERROR Synchronization FAILED. In functions/sync_data.py: connect() got an unexpected keyword argument 'client_encoding'
2025-08-15 18:09:36,851 ERROR Error during database insert operation: connect() got an unexpected keyword argument 'client_encoding'
Traceback (most recent call last):
  File "C:\Users\Yakubov\Documents\Development\LansweeperDataService\src\classes\Database.py", line 57, in insert
    await session.execute(insert(table).values(values))
  File "C:\Users\Yakubov\AppData\Local\pypoetry\Cache\virtualenvs\lansweeperdataservice-dSLrnmG5-py3.13\Lib\site-packages\sqlalchemy\ext\asyncio\session.py", line 463, in execute
    result = await greenlet_spawn(
             ^^^^^^^^^^^^^^^^^^^^^
    ...<6 lines>...
    )
    ^
  File "C:\Users\Yakubov\AppData\Local\pypoetry\Cache\virtualenvs\lansweeperdataservice-dSLrnmG5-py3.13\Lib\site-packages\sqlalchemy\util\_concurrency_py3k.py", line 190, in greenlet_spawn
    result = context.switch(*args, **kwargs)
  File "C:\Users\Yakubov\AppData\Local\pypoetry\Cache\virtualenvs\lansweeperdataservice-dSLrnmG5-py3.13\Lib\site-packages\sqlalchemy\orm\session.py", line 2365, in execute
    return self._execute_internal(
           ~~~~~~~~~~~~~~~~~~~~~~^
        statement,
        ^^^^^^^^^^
    ...<4 lines>...
        _add_event=_add_event,
        ^^^^^^^^^^^^^^^^^^^^^^
    )
    ^
  File "C:\Users\Yakubov\AppData\Local\pypoetry\Cache\virtualenvs\lansweeperdataservice-dSLrnmG5-py3.13\Lib\site-packages\sqlalchemy\orm\session.py", line 2241, in _execute_internal
    conn = self._connection_for_bind(bind)
  File "C:\Users\Yakubov\AppData\Local\pypoetry\Cache\virtualenvs\lansweeperdataservice-dSLrnmG5-py3.13\Lib\site-packages\sqlalchemy\orm\session.py", line 2110, in _connection_for_bind
    return trans._connection_for_bind(engine, execution_options)
           ~~~~~~~~~~~~~~~~~~~~~~~~~~^^^^^^^^^^^^^^^^^^^^^^^^^^^
  File "<string>", line 2, in _connection_for_bind
  File "C:\Users\Yakubov\AppData\Local\pypoetry\Cache\virtualenvs\lansweeperdataservice-dSLrnmG5-py3.13\Lib\site-packages\sqlalchemy\orm\state_changes.py", line 139, in _go
    ret_value = fn(self, *arg, **kw)
  File "C:\Users\Yakubov\AppData\Local\pypoetry\Cache\virtualenvs\lansweeperdataservice-dSLrnmG5-py3.13\Lib\site-packages\sqlalchemy\orm\session.py", line 1189, in _connection_for_bind
    conn = bind.connect()
  File "C:\Users\Yakubov\AppData\Local\pypoetry\Cache\virtualenvs\lansweeperdataservice-dSLrnmG5-py3.13\Lib\site-packages\sqlalchemy\engine\base.py", line 3273, in connect
    return self._connection_cls(self)
           ~~~~~~~~~~~~~~~~~~~~^^^^^^
  File "C:\Users\Yakubov\AppData\Local\pypoetry\Cache\virtualenvs\lansweeperdataservice-dSLrnmG5-py3.13\Lib\site-packages\sqlalchemy\engine\base.py", line 145, in __init__
    self._dbapi_connection = engine.raw_connection()
                             ~~~~~~~~~~~~~~~~~~~~~^^
  File "C:\Users\Yakubov\AppData\Local\pypoetry\Cache\virtualenvs\lansweeperdataservice-dSLrnmG5-py3.13\Lib\site-packages\sqlalchemy\engine\base.py", line 3297, in raw_connection
    return self.pool.connect()
           ~~~~~~~~~~~~~~~~~^^
  File "C:\Users\Yakubov\AppData\Local\pypoetry\Cache\virtualenvs\lansweeperdataservice-dSLrnmG5-py3.13\Lib\site-packages\sqlalchemy\pool\base.py", line 449, in connect
    return _ConnectionFairy._checkout(self)
           ~~~~~~~~~~~~~~~~~~~~~~~~~~^^^^^^
  File "C:\Users\Yakubov\AppData\Local\pypoetry\Cache\virtualenvs\lansweeperdataservice-dSLrnmG5-py3.13\Lib\site-packages\sqlalchemy\pool\base.py", line 1264, in _checkout
    fairy = _ConnectionRecord.checkout(pool)
  File "C:\Users\Yakubov\AppData\Local\pypoetry\Cache\virtualenvs\lansweeperdataservice-dSLrnmG5-py3.13\Lib\site-packages\sqlalchemy\pool\base.py", line 713, in checkout
    rec = pool._do_get()
  File "C:\Users\Yakubov\AppData\Local\pypoetry\Cache\virtualenvs\lansweeperdataservice-dSLrnmG5-py3.13\Lib\site-packages\sqlalchemy\pool\impl.py", line 179, in _do_get
    with util.safe_reraise():
         ~~~~~~~~~~~~~~~~~^^
  File "C:\Users\Yakubov\AppData\Local\pypoetry\Cache\virtualenvs\lansweeperdataservice-dSLrnmG5-py3.13\Lib\site-packages\sqlalchemy\util\langhelpers.py", line 224, in __exit__
    raise exc_value.with_traceback(exc_tb)
  File "C:\Users\Yakubov\AppData\Local\pypoetry\Cache\virtualenvs\lansweeperdataservice-dSLrnmG5-py3.13\Lib\site-packages\sqlalchemy\pool\impl.py", line 177, in _do_get
    return self._create_connection()
           ~~~~~~~~~~~~~~~~~~~~~~~^^
  File "C:\Users\Yakubov\AppData\Local\pypoetry\Cache\virtualenvs\lansweeperdataservice-dSLrnmG5-py3.13\Lib\site-packages\sqlalchemy\pool\base.py", line 390, in _create_connection
    return _ConnectionRecord(self)
  File "C:\Users\Yakubov\AppData\Local\pypoetry\Cache\virtualenvs\lansweeperdataservice-dSLrnmG5-py3.13\Lib\site-packages\sqlalchemy\pool\base.py", line 675, in __init__
    self.__connect()
    ~~~~~~~~~~~~~~^^
  File "C:\Users\Yakubov\AppData\Local\pypoetry\Cache\virtualenvs\lansweeperdataservice-dSLrnmG5-py3.13\Lib\site-packages\sqlalchemy\pool\base.py", line 901, in __connect
    with util.safe_reraise():
         ~~~~~~~~~~~~~~~~~^^
  File "C:\Users\Yakubov\AppData\Local\pypoetry\Cache\virtualenvs\lansweeperdataservice-dSLrnmG5-py3.13\Lib\site-packages\sqlalchemy\util\langhelpers.py", line 224, in __exit__
    raise exc_value.with_traceback(exc_tb)
  File "C:\Users\Yakubov\AppData\Local\pypoetry\Cache\virtualenvs\lansweeperdataservice-dSLrnmG5-py3.13\Lib\site-packages\sqlalchemy\pool\base.py", line 897, in __connect
    self.dbapi_connection = connection = pool._invoke_creator(self)
                                         ~~~~~~~~~~~~~~~~~~~~^^^^^^
  File "C:\Users\Yakubov\AppData\Local\pypoetry\Cache\virtualenvs\lansweeperdataservice-dSLrnmG5-py3.13\Lib\site-packages\sqlalchemy\engine\create.py", line 646, in connect
    return dialect.connect(*cargs, **cparams)
           ~~~~~~~~~~~~~~~^^^^^^^^^^^^^^^^^^^
  File "C:\Users\Yakubov\AppData\Local\pypoetry\Cache\virtualenvs\lansweeperdataservice-dSLrnmG5-py3.13\Lib\site-packages\sqlalchemy\engine\default.py", line 625, in connect
    return self.loaded_dbapi.connect(*cargs, **cparams)  # type: ignore[no-any-return]  # NOQA: E501
           ~~~~~~~~~~~~~~~~~~~~~~~~~^^^^^^^^^^^^^^^^^^^
  File "C:\Users\Yakubov\AppData\Local\pypoetry\Cache\virtualenvs\lansweeperdataservice-dSLrnmG5-py3.13\Lib\site-packages\sqlalchemy\dialects\postgresql\asyncpg.py", line 961, in connect
    await_only(creator_fn(*arg, **kw)),
               ~~~~~~~~~~^^^^^^^^^^^^
TypeError: connect() got an unexpected keyword argument 'client_encoding'
2025-08-15 18:09:36,863 ERROR Synchronization error: connect() got an unexpected keyword argument 'client_encoding'
Traceback (most recent call last):
  File "C:\Users\Yakubov\Documents\Development\LansweeperDataService\src\sync.py", line 25, in sync
    await service.insert(
    ...<2 lines>...
    )
  File "C:\Users\Yakubov\Documents\Development\LansweeperDataService\src\classes\Database.py", line 64, in insert
    raise e
  File "C:\Users\Yakubov\Documents\Development\LansweeperDataService\src\classes\Database.py", line 57, in insert
    await session.execute(insert(table).values(values))
  File "C:\Users\Yakubov\AppData\Local\pypoetry\Cache\virtualenvs\lansweeperdataservice-dSLrnmG5-py3.13\Lib\site-packages\sqlalchemy\ext\asyncio\session.py", line 463, in execute
    result = await greenlet_spawn(
             ^^^^^^^^^^^^^^^^^^^^^
    ...<6 lines>...
    )
    ^
  File "C:\Users\Yakubov\AppData\Local\pypoetry\Cache\virtualenvs\lansweeperdataservice-dSLrnmG5-py3.13\Lib\site-packages\sqlalchemy\util\_concurrency_py3k.py", line 190, in greenlet_spawn
    result = context.switch(*args, **kwargs)
  File "C:\Users\Yakubov\AppData\Local\pypoetry\Cache\virtualenvs\lansweeperdataservice-dSLrnmG5-py3.13\Lib\site-packages\sqlalchemy\orm\session.py", line 2365, in execute
    return self._execute_internal(
           ~~~~~~~~~~~~~~~~~~~~~~^
        statement,
        ^^^^^^^^^^
    ...<4 lines>...
        _add_event=_add_event,
        ^^^^^^^^^^^^^^^^^^^^^^
    )
    ^
  File "C:\Users\Yakubov\AppData\Local\pypoetry\Cache\virtualenvs\lansweeperdataservice-dSLrnmG5-py3.13\Lib\site-packages\sqlalchemy\orm\session.py", line 2241, in _execute_internal
    conn = self._connection_for_bind(bind)
  File "C:\Users\Yakubov\AppData\Local\pypoetry\Cache\virtualenvs\lansweeperdataservice-dSLrnmG5-py3.13\Lib\site-packages\sqlalchemy\orm\session.py", line 2110, in _connection_for_bind
    return trans._connection_for_bind(engine, execution_options)
           ~~~~~~~~~~~~~~~~~~~~~~~~~~^^^^^^^^^^^^^^^^^^^^^^^^^^^
  File "<string>", line 2, in _connection_for_bind
  File "C:\Users\Yakubov\AppData\Local\pypoetry\Cache\virtualenvs\lansweeperdataservice-dSLrnmG5-py3.13\Lib\site-packages\sqlalchemy\orm\state_changes.py", line 139, in _go
    ret_value = fn(self, *arg, **kw)
  File "C:\Users\Yakubov\AppData\Local\pypoetry\Cache\virtualenvs\lansweeperdataservice-dSLrnmG5-py3.13\Lib\site-packages\sqlalchemy\orm\session.py", line 1189, in _connection_for_bind
    conn = bind.connect()
  File "C:\Users\Yakubov\AppData\Local\pypoetry\Cache\virtualenvs\lansweeperdataservice-dSLrnmG5-py3.13\Lib\site-packages\sqlalchemy\engine\base.py", line 3273, in connect
    return self._connection_cls(self)
           ~~~~~~~~~~~~~~~~~~~~^^^^^^
  File "C:\Users\Yakubov\AppData\Local\pypoetry\Cache\virtualenvs\lansweeperdataservice-dSLrnmG5-py3.13\Lib\site-packages\sqlalchemy\engine\base.py", line 145, in __init__
    self._dbapi_connection = engine.raw_connection()
                             ~~~~~~~~~~~~~~~~~~~~~^^
  File "C:\Users\Yakubov\AppData\Local\pypoetry\Cache\virtualenvs\lansweeperdataservice-dSLrnmG5-py3.13\Lib\site-packages\sqlalchemy\engine\base.py", line 3297, in raw_connection
    return self.pool.connect()
           ~~~~~~~~~~~~~~~~~^^
  File "C:\Users\Yakubov\AppData\Local\pypoetry\Cache\virtualenvs\lansweeperdataservice-dSLrnmG5-py3.13\Lib\site-packages\sqlalchemy\pool\base.py", line 449, in connect
    return _ConnectionFairy._checkout(self)
           ~~~~~~~~~~~~~~~~~~~~~~~~~~^^^^^^
  File "C:\Users\Yakubov\AppData\Local\pypoetry\Cache\virtualenvs\lansweeperdataservice-dSLrnmG5-py3.13\Lib\site-packages\sqlalchemy\pool\base.py", line 1264, in _checkout
    fairy = _ConnectionRecord.checkout(pool)
  File "C:\Users\Yakubov\AppData\Local\pypoetry\Cache\virtualenvs\lansweeperdataservice-dSLrnmG5-py3.13\Lib\site-packages\sqlalchemy\pool\base.py", line 713, in checkout
    rec = pool._do_get()
  File "C:\Users\Yakubov\AppData\Local\pypoetry\Cache\virtualenvs\lansweeperdataservice-dSLrnmG5-py3.13\Lib\site-packages\sqlalchemy\pool\impl.py", line 179, in _do_get
    with util.safe_reraise():
         ~~~~~~~~~~~~~~~~~^^
  File "C:\Users\Yakubov\AppData\Local\pypoetry\Cache\virtualenvs\lansweeperdataservice-dSLrnmG5-py3.13\Lib\site-packages\sqlalchemy\util\langhelpers.py", line 224, in __exit__
    raise exc_value.with_traceback(exc_tb)
  File "C:\Users\Yakubov\AppData\Local\pypoetry\Cache\virtualenvs\lansweeperdataservice-dSLrnmG5-py3.13\Lib\site-packages\sqlalchemy\pool\impl.py", line 177, in _do_get
    return self._create_connection()
           ~~~~~~~~~~~~~~~~~~~~~~~^^
  File "C:\Users\Yakubov\AppData\Local\pypoetry\Cache\virtualenvs\lansweeperdataservice-dSLrnmG5-py3.13\Lib\site-packages\sqlalchemy\pool\base.py", line 390, in _create_connection
    return _ConnectionRecord(self)
  File "C:\Users\Yakubov\AppData\Local\pypoetry\Cache\virtualenvs\lansweeperdataservice-dSLrnmG5-py3.13\Lib\site-packages\sqlalchemy\pool\base.py", line 675, in __init__
    self.__connect()
    ~~~~~~~~~~~~~~^^
  File "C:\Users\Yakubov\AppData\Local\pypoetry\Cache\virtualenvs\lansweeperdataservice-dSLrnmG5-py3.13\Lib\site-packages\sqlalchemy\pool\base.py", line 901, in __connect
    with util.safe_reraise():
         ~~~~~~~~~~~~~~~~~^^
  File "C:\Users\Yakubov\AppData\Local\pypoetry\Cache\virtualenvs\lansweeperdataservice-dSLrnmG5-py3.13\Lib\site-packages\sqlalchemy\util\langhelpers.py", line 224, in __exit__
    raise exc_value.with_traceback(exc_tb)
  File "C:\Users\Yakubov\AppData\Local\pypoetry\Cache\virtualenvs\lansweeperdataservice-dSLrnmG5-py3.13\Lib\site-packages\sqlalchemy\pool\base.py", line 897, in __connect
    self.dbapi_connection = connection = pool._invoke_creator(self)
                                         ~~~~~~~~~~~~~~~~~~~~^^^^^^
  File "C:\Users\Yakubov\AppData\Local\pypoetry\Cache\virtualenvs\lansweeperdataservice-dSLrnmG5-py3.13\Lib\site-packages\sqlalchemy\engine\create.py", line 646, in connect
    return dialect.connect(*cargs, **cparams)
           ~~~~~~~~~~~~~~~^^^^^^^^^^^^^^^^^^^
  File "C:\Users\Yakubov\AppData\Local\pypoetry\Cache\virtualenvs\lansweeperdataservice-dSLrnmG5-py3.13\Lib\site-packages\sqlalchemy\engine\default.py", line 625, in connect
    return self.loaded_dbapi.connect(*cargs, **cparams)  # type: ignore[no-any-return]  # NOQA: E501
           ~~~~~~~~~~~~~~~~~~~~~~~~~^^^^^^^^^^^^^^^^^^^
  File "C:\Users\Yakubov\AppData\Local\pypoetry\Cache\virtualenvs\lansweeperdataservice-dSLrnmG5-py3.13\Lib\site-packages\sqlalchemy\dialects\postgresql\asyncpg.py", line 961, in connect
    await_only(creator_fn(*arg, **kw)),
               ~~~~~~~~~~^^^^^^^^^^^^
TypeError: connect() got an unexpected keyword argument 'client_encoding'
2025-08-15 18:09:36,877 INFO END
2025-08-15 18:09:36,877 ERROR Task exception was never retrieved
future: <Task finished name='Task-5' coro=<sync() done, defined at C:\Users\Yakubov\Documents\Development\LansweeperDataService\src\sync.py:12> exception=TypeError("connect() got an unexpected keyword argument 'client_encoding'")>
Traceback (most recent call last):
  File "C:\Users\Yakubov\Documents\Development\LansweeperDataService\src\sync.py", line 32, in sync
    raise e
  File "C:\Users\Yakubov\Documents\Development\LansweeperDataService\src\sync.py", line 25, in sync
    await service.insert(
    ...<2 lines>...
    )
  File "C:\Users\Yakubov\Documents\Development\LansweeperDataService\src\classes\Database.py", line 64, in insert
    raise e
  File "C:\Users\Yakubov\Documents\Development\LansweeperDataService\src\classes\Database.py", line 57, in insert
    await session.execute(insert(table).values(values))
  File "C:\Users\Yakubov\AppData\Local\pypoetry\Cache\virtualenvs\lansweeperdataservice-dSLrnmG5-py3.13\Lib\site-packages\sqlalchemy\ext\asyncio\session.py", line 463, in execute
    result = await greenlet_spawn(
             ^^^^^^^^^^^^^^^^^^^^^
    ...<6 lines>...
    )
    ^
  File "C:\Users\Yakubov\AppData\Local\pypoetry\Cache\virtualenvs\lansweeperdataservice-dSLrnmG5-py3.13\Lib\site-packages\sqlalchemy\util\_concurrency_py3k.py", line 190, in greenlet_spawn
    result = context.switch(*args, **kwargs)
  File "C:\Users\Yakubov\AppData\Local\pypoetry\Cache\virtualenvs\lansweeperdataservice-dSLrnmG5-py3.13\Lib\site-packages\sqlalchemy\orm\session.py", line 2365, in execute
    return self._execute_internal(
           ~~~~~~~~~~~~~~~~~~~~~~^
        statement,
        ^^^^^^^^^^
    ...<4 lines>...
        _add_event=_add_event,
        ^^^^^^^^^^^^^^^^^^^^^^
    )
    ^
  File "C:\Users\Yakubov\AppData\Local\pypoetry\Cache\virtualenvs\lansweeperdataservice-dSLrnmG5-py3.13\Lib\site-packages\sqlalchemy\orm\session.py", line 2241, in _execute_internal
    conn = self._connection_for_bind(bind)
  File "C:\Users\Yakubov\AppData\Local\pypoetry\Cache\virtualenvs\lansweeperdataservice-dSLrnmG5-py3.13\Lib\site-packages\sqlalchemy\orm\session.py", line 2110, in _connection_for_bind
    return trans._connection_for_bind(engine, execution_options)
           ~~~~~~~~~~~~~~~~~~~~~~~~~~^^^^^^^^^^^^^^^^^^^^^^^^^^^
  File "<string>", line 2, in _connection_for_bind
  File "C:\Users\Yakubov\AppData\Local\pypoetry\Cache\virtualenvs\lansweeperdataservice-dSLrnmG5-py3.13\Lib\site-packages\sqlalchemy\orm\state_changes.py", line 139, in _go
    ret_value = fn(self, *arg, **kw)
  File "C:\Users\Yakubov\AppData\Local\pypoetry\Cache\virtualenvs\lansweeperdataservice-dSLrnmG5-py3.13\Lib\site-packages\sqlalchemy\orm\session.py", line 1189, in _connection_for_bind
    conn = bind.connect()
  File "C:\Users\Yakubov\AppData\Local\pypoetry\Cache\virtualenvs\lansweeperdataservice-dSLrnmG5-py3.13\Lib\site-packages\sqlalchemy\engine\base.py", line 3273, in connect
    return self._connection_cls(self)
           ~~~~~~~~~~~~~~~~~~~~^^^^^^
  File "C:\Users\Yakubov\AppData\Local\pypoetry\Cache\virtualenvs\lansweeperdataservice-dSLrnmG5-py3.13\Lib\site-packages\sqlalchemy\engine\base.py", line 145, in __init__
    self._dbapi_connection = engine.raw_connection()
                             ~~~~~~~~~~~~~~~~~~~~~^^
  File "C:\Users\Yakubov\AppData\Local\pypoetry\Cache\virtualenvs\lansweeperdataservice-dSLrnmG5-py3.13\Lib\site-packages\sqlalchemy\engine\base.py", line 3297, in raw_connection
    return self.pool.connect()
           ~~~~~~~~~~~~~~~~~^^
  File "C:\Users\Yakubov\AppData\Local\pypoetry\Cache\virtualenvs\lansweeperdataservice-dSLrnmG5-py3.13\Lib\site-packages\sqlalchemy\pool\base.py", line 449, in connect
    return _ConnectionFairy._checkout(self)
           ~~~~~~~~~~~~~~~~~~~~~~~~~~^^^^^^
  File "C:\Users\Yakubov\AppData\Local\pypoetry\Cache\virtualenvs\lansweeperdataservice-dSLrnmG5-py3.13\Lib\site-packages\sqlalchemy\pool\base.py", line 1264, in _checkout
    fairy = _ConnectionRecord.checkout(pool)
  File "C:\Users\Yakubov\AppData\Local\pypoetry\Cache\virtualenvs\lansweeperdataservice-dSLrnmG5-py3.13\Lib\site-packages\sqlalchemy\pool\base.py", line 713, in checkout
    rec = pool._do_get()
  File "C:\Users\Yakubov\AppData\Local\pypoetry\Cache\virtualenvs\lansweeperdataservice-dSLrnmG5-py3.13\Lib\site-packages\sqlalchemy\pool\impl.py", line 179, in _do_get
    with util.safe_reraise():
         ~~~~~~~~~~~~~~~~~^^
  File "C:\Users\Yakubov\AppData\Local\pypoetry\Cache\virtualenvs\lansweeperdataservice-dSLrnmG5-py3.13\Lib\site-packages\sqlalchemy\util\langhelpers.py", line 224, in __exit__
    raise exc_value.with_traceback(exc_tb)
  File "C:\Users\Yakubov\AppData\Local\pypoetry\Cache\virtualenvs\lansweeperdataservice-dSLrnmG5-py3.13\Lib\site-packages\sqlalchemy\pool\impl.py", line 177, in _do_get
    return self._create_connection()
           ~~~~~~~~~~~~~~~~~~~~~~~^^
  File "C:\Users\Yakubov\AppData\Local\pypoetry\Cache\virtualenvs\lansweeperdataservice-dSLrnmG5-py3.13\Lib\site-packages\sqlalchemy\pool\base.py", line 390, in _create_connection
    return _ConnectionRecord(self)
  File "C:\Users\Yakubov\AppData\Local\pypoetry\Cache\virtualenvs\lansweeperdataservice-dSLrnmG5-py3.13\Lib\site-packages\sqlalchemy\pool\base.py", line 675, in __init__
    self.__connect()
    ~~~~~~~~~~~~~~^^
  File "C:\Users\Yakubov\AppData\Local\pypoetry\Cache\virtualenvs\lansweeperdataservice-dSLrnmG5-py3.13\Lib\site-packages\sqlalchemy\pool\base.py", line 901, in __connect
    with util.safe_reraise():
         ~~~~~~~~~~~~~~~~~^^
  File "C:\Users\Yakubov\AppData\Local\pypoetry\Cache\virtualenvs\lansweeperdataservice-dSLrnmG5-py3.13\Lib\site-packages\sqlalchemy\util\langhelpers.py", line 224, in __exit__
    raise exc_value.with_traceback(exc_tb)
  File "C:\Users\Yakubov\AppData\Local\pypoetry\Cache\virtualenvs\lansweeperdataservice-dSLrnmG5-py3.13\Lib\site-packages\sqlalchemy\pool\base.py", line 897, in __connect
    self.dbapi_connection = connection = pool._invoke_creator(self)
                                         ~~~~~~~~~~~~~~~~~~~~^^^^^^
  File "C:\Users\Yakubov\AppData\Local\pypoetry\Cache\virtualenvs\lansweeperdataservice-dSLrnmG5-py3.13\Lib\site-packages\sqlalchemy\engine\create.py", line 646, in connect
    return dialect.connect(*cargs, **cparams)
           ~~~~~~~~~~~~~~~^^^^^^^^^^^^^^^^^^^
  File "C:\Users\Yakubov\AppData\Local\pypoetry\Cache\virtualenvs\lansweeperdataservice-dSLrnmG5-py3.13\Lib\site-packages\sqlalchemy\engine\default.py", line 625, in connect
    return self.loaded_dbapi.connect(*cargs, **cparams)  # type: ignore[no-any-return]  # NOQA: E501
           ~~~~~~~~~~~~~~~~~~~~~~~~~^^^^^^^^^^^^^^^^^^^
  File "C:\Users\Yakubov\AppData\Local\pypoetry\Cache\virtualenvs\lansweeperdataservice-dSLrnmG5-py3.13\Lib\site-packages\sqlalchemy\dialects\postgresql\asyncpg.py", line 961, in connect
    await_only(creator_fn(*arg, **kw)),
               ~~~~~~~~~~^^^^^^^^^^^^
TypeError: connect() got an unexpected keyword argument 'client_encoding'
2025-08-15 18:09:56,595 ERROR Unclosed connection
connection: <aioodbc.connection.Connection object at 0x000002A147C797F0>
2025-08-15 18:10:01,616 INFO API - handle /start-sync request
2025-08-15 18:10:01,618 INFO START
2025-08-15 18:10:01,739 INFO START Synchronization..
2025-08-15 18:10:09,519 INFO END
2025-08-15 18:18:40,513 INFO API server STARTED
2025-08-15 18:18:40,514 INFO Start base migration
2025-08-15 18:18:45,379 INFO API - handle /start-sync request
2025-08-15 18:18:45,382 INFO START
2025-08-15 18:18:45,497 INFO START Synchronization..
2025-08-15 18:19:41,914 INFO END
2025-08-15 18:19:41,987 ERROR Unclosed connection
connection: <aioodbc.connection.Connection object at 0x0000020915F997F0>
2025-08-15 18:19:54,308 INFO API - handle /start-sync request
2025-08-15 18:19:54,311 INFO START
2025-08-15 18:19:54,433 INFO START Synchronization..
2025-08-15 18:20:17,174 INFO Synchronization COMPLETED. Added 504 servers in service database
2025-08-15 18:20:17,208 INFO END
2025-08-15 18:21:24,771 ERROR Unclosed connection
connection: <aioodbc.connection.Connection object at 0x0000017A4D7B57F0>
