2025-08-20 13:20:11,939 INFO API server STARTED
2025-08-20 13:20:11,940 INFO Start base migration
2025-08-20 13:20:30,939 INFO API - handle /hosts request
2025-08-20 13:21:46,382 INFO API - handle /hosts request
2025-08-20 13:33:49,467 INFO API server STARTED
2025-08-20 13:33:49,467 INFO Start base migration
2025-08-20 13:34:02,935 INFO API - handle /hosts request
2025-08-20 13:34:38,559 INFO API - handle /host
2025-08-20 13:35:09,989 INFO API server STARTED
2025-08-20 13:35:09,989 INFO Start base migration
2025-08-20 13:35:27,401 INFO API - handle /start-sync request
2025-08-20 13:35:27,403 INFO START
2025-08-20 13:35:27,720 INFO START Synchronization..
2025-08-20 13:35:29,256 ERROR Error during database select operation: (sqlalchemy.dialects.postgresql.asyncpg.ProgrammingError) <class 'asyncpg.exceptions.UndefinedColumnError'>: column lansweeper_data.customs does not exist
[SQL: SELECT integration_modules.lansweeper_data.host_id, integration_modules.lansweeper_data.asset_id, integration_modules.lansweeper_data.name, integration_modules.lansweeper_data.typename, integration_modules.lansweeper_data.operating_system, integration_modules.lansweeper_data.ou, integration_modules.lansweeper_data.ip_address, integration_modules.lansweeper_data.mac, integration_modules.lansweeper_data.processor, integration_modules.lansweeper_data.first_seen, integration_modules.lansweeper_data.description, integration_modules.lansweeper_data.manufacturer, integration_modules.lansweeper_data.model, integration_modules.lansweeper_data.serial_number, integration_modules.lansweeper_data.detected, integration_modules.lansweeper_data.customs 
FROM integration_modules.lansweeper_data]
(Background on this error at: https://sqlalche.me/e/20/f405)
Traceback (most recent call last):
  File "C:\Users\Yakubov\AppData\Local\pypoetry\Cache\virtualenvs\lansweeperdataservice-dSLrnmG5-py3.13\Lib\site-packages\sqlalchemy\dialects\postgresql\asyncpg.py", line 521, in _prepare_and_execute
    prepared_stmt, attributes = await adapt_connection._prepare(
                                ^^^^^^^^^^^^^^^^^^^^^^^^^^^^^^^^
        operation, self._invalidate_schema_cache_asof
        ^^^^^^^^^^^^^^^^^^^^^^^^^^^^^^^^^^^^^^^^^^^^^
    )
    ^
  File "C:\Users\Yakubov\AppData\Local\pypoetry\Cache\virtualenvs\lansweeperdataservice-dSLrnmG5-py3.13\Lib\site-packages\sqlalchemy\dialects\postgresql\asyncpg.py", line 768, in _prepare
    prepared_stmt = await self._connection.prepare(
                    ^^^^^^^^^^^^^^^^^^^^^^^^^^^^^^^
        operation, name=self._prepared_statement_name_func()
        ^^^^^^^^^^^^^^^^^^^^^^^^^^^^^^^^^^^^^^^^^^^^^^^^^^^^
    )
    ^
  File "C:\Users\Yakubov\AppData\Local\pypoetry\Cache\virtualenvs\lansweeperdataservice-dSLrnmG5-py3.13\Lib\site-packages\asyncpg\connection.py", line 635, in prepare
    return await self._prepare(
           ^^^^^^^^^^^^^^^^^^^^
    ...<5 lines>...
    )
    ^
  File "C:\Users\Yakubov\AppData\Local\pypoetry\Cache\virtualenvs\lansweeperdataservice-dSLrnmG5-py3.13\Lib\site-packages\asyncpg\connection.py", line 653, in _prepare
    stmt = await self._get_statement(
           ^^^^^^^^^^^^^^^^^^^^^^^^^^
    ...<5 lines>...
    )
    ^
  File "C:\Users\Yakubov\AppData\Local\pypoetry\Cache\virtualenvs\lansweeperdataservice-dSLrnmG5-py3.13\Lib\site-packages\asyncpg\connection.py", line 432, in _get_statement
    statement = await self._protocol.prepare(
                ^^^^^^^^^^^^^^^^^^^^^^^^^^^^^
    ...<5 lines>...
    )
    ^
  File "asyncpg\\protocol\\protocol.pyx", line 165, in prepare
asyncpg.exceptions.UndefinedColumnError: column lansweeper_data.customs does not exist

The above exception was the direct cause of the following exception:

Traceback (most recent call last):
  File "C:\Users\Yakubov\AppData\Local\pypoetry\Cache\virtualenvs\lansweeperdataservice-dSLrnmG5-py3.13\Lib\site-packages\sqlalchemy\engine\base.py", line 1963, in _exec_single_context
    self.dialect.do_execute(
    ~~~~~~~~~~~~~~~~~~~~~~~^
        cursor, str_statement, effective_parameters, context
        ^^^^^^^^^^^^^^^^^^^^^^^^^^^^^^^^^^^^^^^^^^^^^^^^^^^^
    )
    ^
  File "C:\Users\Yakubov\AppData\Local\pypoetry\Cache\virtualenvs\lansweeperdataservice-dSLrnmG5-py3.13\Lib\site-packages\sqlalchemy\engine\default.py", line 943, in do_execute
    cursor.execute(statement, parameters)
    ~~~~~~~~~~~~~~^^^^^^^^^^^^^^^^^^^^^^^
  File "C:\Users\Yakubov\AppData\Local\pypoetry\Cache\virtualenvs\lansweeperdataservice-dSLrnmG5-py3.13\Lib\site-packages\sqlalchemy\dialects\postgresql\asyncpg.py", line 580, in execute
    self._adapt_connection.await_(
    ~~~~~~~~~~~~~~~~~~~~~~~~~~~~~^
        self._prepare_and_execute(operation, parameters)
        ^^^^^^^^^^^^^^^^^^^^^^^^^^^^^^^^^^^^^^^^^^^^^^^^
    )
    ^
  File "C:\Users\Yakubov\AppData\Local\pypoetry\Cache\virtualenvs\lansweeperdataservice-dSLrnmG5-py3.13\Lib\site-packages\sqlalchemy\util\_concurrency_py3k.py", line 132, in await_only
    return current.parent.switch(awaitable)  # type: ignore[no-any-return,attr-defined] # noqa: E501
           ~~~~~~~~~~~~~~~~~~~~~^^^^^^^^^^^
  File "C:\Users\Yakubov\AppData\Local\pypoetry\Cache\virtualenvs\lansweeperdataservice-dSLrnmG5-py3.13\Lib\site-packages\sqlalchemy\util\_concurrency_py3k.py", line 196, in greenlet_spawn
    value = await result
            ^^^^^^^^^^^^
  File "C:\Users\Yakubov\AppData\Local\pypoetry\Cache\virtualenvs\lansweeperdataservice-dSLrnmG5-py3.13\Lib\site-packages\sqlalchemy\dialects\postgresql\asyncpg.py", line 558, in _prepare_and_execute
    self._handle_exception(error)
    ~~~~~~~~~~~~~~~~~~~~~~^^^^^^^
  File "C:\Users\Yakubov\AppData\Local\pypoetry\Cache\virtualenvs\lansweeperdataservice-dSLrnmG5-py3.13\Lib\site-packages\sqlalchemy\dialects\postgresql\asyncpg.py", line 508, in _handle_exception
    self._adapt_connection._handle_exception(error)
    ~~~~~~~~~~~~~~~~~~~~~~~~~~~~~~~~~~~~~~~~^^^^^^^
  File "C:\Users\Yakubov\AppData\Local\pypoetry\Cache\virtualenvs\lansweeperdataservice-dSLrnmG5-py3.13\Lib\site-packages\sqlalchemy\dialects\postgresql\asyncpg.py", line 792, in _handle_exception
    raise translated_error from error
sqlalchemy.dialects.postgresql.asyncpg.AsyncAdapt_asyncpg_dbapi.ProgrammingError: <class 'asyncpg.exceptions.UndefinedColumnError'>: column lansweeper_data.customs does not exist

The above exception was the direct cause of the following exception:

Traceback (most recent call last):
  File "C:\Users\Yakubov\Documents\Development\LansweeperDataService\src\classes\Database.py", line 31, in select
    result = await session.execute(query)
             ^^^^^^^^^^^^^^^^^^^^^^^^^^^^
  File "C:\Users\Yakubov\AppData\Local\pypoetry\Cache\virtualenvs\lansweeperdataservice-dSLrnmG5-py3.13\Lib\site-packages\sqlalchemy\ext\asyncio\session.py", line 463, in execute
    result = await greenlet_spawn(
             ^^^^^^^^^^^^^^^^^^^^^
    ...<6 lines>...
    )
    ^
  File "C:\Users\Yakubov\AppData\Local\pypoetry\Cache\virtualenvs\lansweeperdataservice-dSLrnmG5-py3.13\Lib\site-packages\sqlalchemy\util\_concurrency_py3k.py", line 201, in greenlet_spawn
    result = context.throw(*sys.exc_info())
  File "C:\Users\Yakubov\AppData\Local\pypoetry\Cache\virtualenvs\lansweeperdataservice-dSLrnmG5-py3.13\Lib\site-packages\sqlalchemy\orm\session.py", line 2365, in execute
    return self._execute_internal(
           ~~~~~~~~~~~~~~~~~~~~~~^
        statement,
        ^^^^^^^^^^
    ...<4 lines>...
        _add_event=_add_event,
        ^^^^^^^^^^^^^^^^^^^^^^
    )
    ^
  File "C:\Users\Yakubov\AppData\Local\pypoetry\Cache\virtualenvs\lansweeperdataservice-dSLrnmG5-py3.13\Lib\site-packages\sqlalchemy\orm\session.py", line 2251, in _execute_internal
    result: Result[Any] = compile_state_cls.orm_execute_statement(
                          ~~~~~~~~~~~~~~~~~~~~~~~~~~~~~~~~~~~~~~~^
        self,
        ^^^^^
    ...<4 lines>...
        conn,
        ^^^^^
    )
    ^
  File "C:\Users\Yakubov\AppData\Local\pypoetry\Cache\virtualenvs\lansweeperdataservice-dSLrnmG5-py3.13\Lib\site-packages\sqlalchemy\orm\context.py", line 306, in orm_execute_statement
    result = conn.execute(
        statement, params or {}, execution_options=execution_options
    )
  File "C:\Users\Yakubov\AppData\Local\pypoetry\Cache\virtualenvs\lansweeperdataservice-dSLrnmG5-py3.13\Lib\site-packages\sqlalchemy\engine\base.py", line 1415, in execute
    return meth(
        self,
        distilled_parameters,
        execution_options or NO_OPTIONS,
    )
  File "C:\Users\Yakubov\AppData\Local\pypoetry\Cache\virtualenvs\lansweeperdataservice-dSLrnmG5-py3.13\Lib\site-packages\sqlalchemy\sql\elements.py", line 523, in _execute_on_connection
    return connection._execute_clauseelement(
           ~~~~~~~~~~~~~~~~~~~~~~~~~~~~~~~~~^
        self, distilled_params, execution_options
        ^^^^^^^^^^^^^^^^^^^^^^^^^^^^^^^^^^^^^^^^^
    )
    ^
  File "C:\Users\Yakubov\AppData\Local\pypoetry\Cache\virtualenvs\lansweeperdataservice-dSLrnmG5-py3.13\Lib\site-packages\sqlalchemy\engine\base.py", line 1637, in _execute_clauseelement
    ret = self._execute_context(
        dialect,
    ...<8 lines>...
        cache_hit=cache_hit,
    )
  File "C:\Users\Yakubov\AppData\Local\pypoetry\Cache\virtualenvs\lansweeperdataservice-dSLrnmG5-py3.13\Lib\site-packages\sqlalchemy\engine\base.py", line 1842, in _execute_context
    return self._exec_single_context(
           ~~~~~~~~~~~~~~~~~~~~~~~~~^
        dialect, context, statement, parameters
        ^^^^^^^^^^^^^^^^^^^^^^^^^^^^^^^^^^^^^^^
    )
    ^
  File "C:\Users\Yakubov\AppData\Local\pypoetry\Cache\virtualenvs\lansweeperdataservice-dSLrnmG5-py3.13\Lib\site-packages\sqlalchemy\engine\base.py", line 1982, in _exec_single_context
    self._handle_dbapi_exception(
    ~~~~~~~~~~~~~~~~~~~~~~~~~~~~^
        e, str_statement, effective_parameters, cursor, context
        ^^^^^^^^^^^^^^^^^^^^^^^^^^^^^^^^^^^^^^^^^^^^^^^^^^^^^^^
    )
    ^
  File "C:\Users\Yakubov\AppData\Local\pypoetry\Cache\virtualenvs\lansweeperdataservice-dSLrnmG5-py3.13\Lib\site-packages\sqlalchemy\engine\base.py", line 2351, in _handle_dbapi_exception
    raise sqlalchemy_exception.with_traceback(exc_info[2]) from e
  File "C:\Users\Yakubov\AppData\Local\pypoetry\Cache\virtualenvs\lansweeperdataservice-dSLrnmG5-py3.13\Lib\site-packages\sqlalchemy\engine\base.py", line 1963, in _exec_single_context
    self.dialect.do_execute(
    ~~~~~~~~~~~~~~~~~~~~~~~^
        cursor, str_statement, effective_parameters, context
        ^^^^^^^^^^^^^^^^^^^^^^^^^^^^^^^^^^^^^^^^^^^^^^^^^^^^
    )
    ^
  File "C:\Users\Yakubov\AppData\Local\pypoetry\Cache\virtualenvs\lansweeperdataservice-dSLrnmG5-py3.13\Lib\site-packages\sqlalchemy\engine\default.py", line 943, in do_execute
    cursor.execute(statement, parameters)
    ~~~~~~~~~~~~~~^^^^^^^^^^^^^^^^^^^^^^^
  File "C:\Users\Yakubov\AppData\Local\pypoetry\Cache\virtualenvs\lansweeperdataservice-dSLrnmG5-py3.13\Lib\site-packages\sqlalchemy\dialects\postgresql\asyncpg.py", line 580, in execute
    self._adapt_connection.await_(
    ~~~~~~~~~~~~~~~~~~~~~~~~~~~~~^
        self._prepare_and_execute(operation, parameters)
        ^^^^^^^^^^^^^^^^^^^^^^^^^^^^^^^^^^^^^^^^^^^^^^^^
    )
    ^
  File "C:\Users\Yakubov\AppData\Local\pypoetry\Cache\virtualenvs\lansweeperdataservice-dSLrnmG5-py3.13\Lib\site-packages\sqlalchemy\util\_concurrency_py3k.py", line 132, in await_only
    return current.parent.switch(awaitable)  # type: ignore[no-any-return,attr-defined] # noqa: E501
           ~~~~~~~~~~~~~~~~~~~~~^^^^^^^^^^^
  File "C:\Users\Yakubov\AppData\Local\pypoetry\Cache\virtualenvs\lansweeperdataservice-dSLrnmG5-py3.13\Lib\site-packages\sqlalchemy\util\_concurrency_py3k.py", line 196, in greenlet_spawn
    value = await result
            ^^^^^^^^^^^^
  File "C:\Users\Yakubov\AppData\Local\pypoetry\Cache\virtualenvs\lansweeperdataservice-dSLrnmG5-py3.13\Lib\site-packages\sqlalchemy\dialects\postgresql\asyncpg.py", line 558, in _prepare_and_execute
    self._handle_exception(error)
    ~~~~~~~~~~~~~~~~~~~~~~^^^^^^^
  File "C:\Users\Yakubov\AppData\Local\pypoetry\Cache\virtualenvs\lansweeperdataservice-dSLrnmG5-py3.13\Lib\site-packages\sqlalchemy\dialects\postgresql\asyncpg.py", line 508, in _handle_exception
    self._adapt_connection._handle_exception(error)
    ~~~~~~~~~~~~~~~~~~~~~~~~~~~~~~~~~~~~~~~~^^^^^^^
  File "C:\Users\Yakubov\AppData\Local\pypoetry\Cache\virtualenvs\lansweeperdataservice-dSLrnmG5-py3.13\Lib\site-packages\sqlalchemy\dialects\postgresql\asyncpg.py", line 792, in _handle_exception
    raise translated_error from error
sqlalchemy.exc.ProgrammingError: (sqlalchemy.dialects.postgresql.asyncpg.ProgrammingError) <class 'asyncpg.exceptions.UndefinedColumnError'>: column lansweeper_data.customs does not exist
[SQL: SELECT integration_modules.lansweeper_data.host_id, integration_modules.lansweeper_data.asset_id, integration_modules.lansweeper_data.name, integration_modules.lansweeper_data.typename, integration_modules.lansweeper_data.operating_system, integration_modules.lansweeper_data.ou, integration_modules.lansweeper_data.ip_address, integration_modules.lansweeper_data.mac, integration_modules.lansweeper_data.processor, integration_modules.lansweeper_data.first_seen, integration_modules.lansweeper_data.description, integration_modules.lansweeper_data.manufacturer, integration_modules.lansweeper_data.model, integration_modules.lansweeper_data.serial_number, integration_modules.lansweeper_data.detected, integration_modules.lansweeper_data.customs 
FROM integration_modules.lansweeper_data]
(Background on this error at: https://sqlalche.me/e/20/f405)
2025-08-20 13:35:29,327 ERROR Synchronization FAILED. In functions/sync_data.py: (sqlalchemy.dialects.postgresql.asyncpg.ProgrammingError) <class 'asyncpg.exceptions.UndefinedColumnError'>: column lansweeper_data.customs does not exist
[SQL: SELECT integration_modules.lansweeper_data.host_id, integration_modules.lansweeper_data.asset_id, integration_modules.lansweeper_data.name, integration_modules.lansweeper_data.typename, integration_modules.lansweeper_data.operating_system, integration_modules.lansweeper_data.ou, integration_modules.lansweeper_data.ip_address, integration_modules.lansweeper_data.mac, integration_modules.lansweeper_data.processor, integration_modules.lansweeper_data.first_seen, integration_modules.lansweeper_data.description, integration_modules.lansweeper_data.manufacturer, integration_modules.lansweeper_data.model, integration_modules.lansweeper_data.serial_number, integration_modules.lansweeper_data.detected, integration_modules.lansweeper_data.customs 
FROM integration_modules.lansweeper_data]
(Background on this error at: https://sqlalche.me/e/20/f405)
2025-08-20 13:35:29,358 INFO END
2025-08-20 13:36:08,844 ERROR Unclosed connection
connection: <aioodbc.connection.Connection object at 0x0000016F18455010>
2025-08-20 13:36:15,943 INFO API server STARTED
2025-08-20 13:36:15,943 INFO Start base migration
2025-08-20 13:36:21,854 INFO API - handle /start-sync request
2025-08-20 13:36:21,857 INFO START
2025-08-20 13:36:21,995 INFO START Synchronization..
2025-08-20 13:37:41,191 INFO Synchronization COMPLETED. Added 2453 servers in service database
2025-08-20 13:37:41,229 INFO END
